Workbook
Name SegmentaciónDeDatos_fecha__mes: #N/A
Name SegmentaciónDeDatos_Producto: #N/A
Name SegmentaciónDeDatos_Producto1: #N/A
Name SegmentaciónDeDatos_Producto2: #N/A
Name SegmentaciónDeDatos_Producto3: #N/A
Name SegmentaciónDeDatos_Producto4: #N/A
Name SegmentaciónDeDatos_Producto5: #N/A
Name SegmentaciónDeDatos_Producto6: #N/A
Name SegmentaciónDeDatos_Producto7: #N/A
Name SegmentaciónDeDatos_Region: #N/A
Name SegmentaciónDeDatos_Region1: #N/A
Name SegmentaciónDeDatos_Region2: #N/A
Name SegmentaciónDeDatos_Region3: #N/A

Sheet NOTAS
A1: NOTAS
J2: DIFERENCIAS
G3: PROMEDIO DIARIO SE CAPTURA MANUAL | J3: CASTILLOS
J5: PLAZA | K5: MA
J6: AGUASCALIENTES | K6: 480
A12: PLAZA | B12: FECHA | C12: VOL - CARO | D12: BASE - CARO | E12: BASE | F12: FILTROS
A13: aguascalientes | B13: 45717 | C13: 494 | D13: 404.55 | E13: 404.55 | F13: PRODUCTO: cemento gris ; PLAZA: aguascalientes ; VOL: marzo25
A14: leon | B14: 45658 | C14: 614 | D14: 568.8 | E14: 568.8 | F14: PRODUCTO: cemento gris ; PLAZA: leon ; VOL: ene25

Sheet PRODUCTOS
B10: Volumen | F10: Año
B11: Region | C11: Gerencia | D11: Plaza | E11: fecha (año) | F11: 2021 | G11: 2022 | H11: 2023 | I11: 2024 | J11: 2025 | K11: 2026
B12: CENTRO-SUR | F12: 239882.55 | G12: 216839.85 | H12: 237410.35 | I12: 255231.02 | J12: 244460.9 | K12: 84004.9
C13: ESTADO DE MEXICO | F13: 14053.32 | G13: 7457.33 | H13: 9171.26 | I13: 8203.3 | J13: 7912.175 | K13: 2895.6
C14: PENINSULA | F14: 37010.39 | G14: 38904.59 | H14: 44179.54 | I14: 47070.75 | J14: 39449.15 | K14: 11436.025
C15: SUR VER-TAB | F15: 22220.85 | G15: 16829.925 | H15: 19364.1 | I15: 17202.75 | J15: 16957.75 | K15: 5934.325
C16: METRO-HIDALGO | F16: 96155.415 | G16: 88256.82 | H16: 92566.81 | I16: 104649.57 | J16: 104703.98 | K16: 35334.05
C17: OAXACA - CHIAPAS | F17: 16488.15 | G17: 15401.03 | H17: 19372.75 | I17: 18227.596 | J17: 14847.775 | K17: 5721.85
C18: PUE-TLAX-MOR | F18: 53954.43 | G18: 49990.155 | H18: 52755.89 | I18: 59877.05 | J18: 60590.075 | K18: 22683.05
B19: NACIONAL | F19: 239882.55 | G19: 216839.85 | H19: 237410.35 | I19: 255231.02 | J19: 244460.9 | K19: 84004.9
B30: Volumen | C30: Año
B31: Mes | C31: 2025 | D31: 2026 | E31: Grand Total
B32: E | C32: 44476.403 | D32: 46049.6 | E32: 90526.003
B33: F | C33: 43886.149 | D33: 46368.031 | E33: 90254.18
B34: M | C34: 43418.272 | D34: 49228.129 | E34: 92646.401
B35: A | C35: 45787.505 | D35: 42082.16 | E35: 87869.665
B36: M | C36: 46828.061 | E36: 46828.061
B37: J | C37: 43426.615 | E37: 43426.615
B38: J | C38: 51183.415 | E38: 51183.415
B39: A | C39: 48386.689 | E39: 48386.689
B40: S | C40: 44862.885 | E40: 44862.885
B41: O | C41: 47688.359 | E41: 47688.359
B42: N | C42: 42581.327 | E42: 42581.327
B43: D | C43: 40777.252 | E43: 40777.252
B44: Grand Total | C44: 543302.93 | D44: 183727.92 | E44: 727030.85
B63: Volumen Base | C63: Column Labels
B64: Row Labels | C64: 2025 | D64: 2026 | E64: Grand Total
B65: E | C65: 9349.025 | D65: 8813.85 | E65: 18162.875
B66: F | C66: 8044.525 | D66: 9480.775 | E66: 17525.3
B67: M | C67: 8245.825 | D67: 8769.6 | E67: 17015.425
B68: A | C68: 8805.525 | D68: 7333.15 | E68: 16138.675
B69: M | C69: 8843.975 | E69: 8843.975
B70: J | C70: 7828.9 | E70: 7828.9
B71: J | C71: 9630.55 | E71: 9630.55
B72: A | C72: 9721.1 | E72: 9721.1
B73: S | C73: 8082.15 | E73: 8082.15
B74: O | C74: 9171.15 | E74: 9171.15
B75: N | C75: 8324.225 | E75: 8324.225
B76: D | C76: 7385.725 | E76: 7385.725
B77: Grand Total | C77: 103432.67 | D77: 34397.375 | E77: 137830.05

Sheet FACT
B2: fecha (año) | C2: 2025
B4: Producto | C4: Importe Jun'25 | D4: Importe May'25 | E4: Importe Abr'25
B5: Antihumedad | C5: 4425416.2 | D5: 5107018.3 | E5: 4130054.9
B6: Asfalto | C6: 568960 | E6: 0
B7: Blanco | C7: 3064804.3 | D7: 3282422 | E7: 3299447.4
B8: Gris | C8: 1.7330869e+08 | D8: 1.8871205e+08 | E8: 1.8206914e+08
B9: Mezclas Secas | C9: 1046331.7 | D9: 851322.78 | E9: 1282065.6
B10: Mortero | C10: 26407026 | D10: 30206206 | E10: 29468313
B11: Multiplast | C11: 5282464.8 | D11: 6093089.8 | E11: 5587018.9
B12: Grand Total | C12: 2.1410369e+08 | D12: 2.3425211e+08 | E12: 2.2583604e+08 | J12: MANUAL
J14: Producto | K14: % Conc. | L14: Importe Abr'26 | M14: Importe Mar'26 | N14: Importe Feb'26 | O14: Importe Ene'26 | P14: Importe Dic'25 | Q14: Importe Nov'25 | R14: Importe Oct'25 | S14: % | T14: Importe Sep'25 | U14: Importe Ago'25 | V14: Importe Jul'25 | W14: Importe Jun'25 | X14: Importe May'25 | Y14: Importe Abr'25
J15: Gris | K15: =+L15/$M$23 -> 0.70770373 | L15: 1.8491603e+08 | M15: 2.0635743e+08 | N15: 1.9756209e+08 | O15: 1.8772495e+08 | P15: 1.6552399e+08 | Q15: 1.7375759e+08 | R15: 1.9464781e+08 | S15: =+Q15/$R$23 -> 0.69692689 | T15: 1.8254247e+08 | U15: 197175178 | V15: 2.0900741e+08 | W15: 1.7330869e+08 | X15: 1.8871205e+08 | Y15: 1.8206914e+08
J16: Mortero | K16: =+L16/$M$23 -> 0.10582877 | L16: 27652018 | M16: 31613955 | N16: 34731901 | O16: 30581230 | P16: 25249973 | Q16: 28591293 | R16: 31754177 | S16: =+Q16/$R$23 -> 0.11467724 | T16: 28220883 | U16: 33786945 | V16: 32854188 | W16: 26407026 | X16: 30206206 | Y16: 29468313
J17: Multiplast | K17: =+L17/$M$23 -> 0.021905027 | L17: 5723568.3 | M17: 5437915 | N17: 4582437.2 | O17: 5467830.8 | P17: 5866902.5 | Q17: 5664189.3 | R17: 6153380 | S17: =+Q17/$R$23 -> 0.02271858 | T17: 6144669.3 | U17: 6518455 | V17: 6710999.3 | W17: 5282464.8 | X17: 6093089.8 | Y17: 5587018.9
J18: Antihumedad | K18: =+L18/$M$23 -> 0.026339405 | L18: 6882227.8 | M18: 6693640.9 | N18: 6043339.1 | O18: 4342744.7 | P18: 4278812.3 | Q18: 4554935.6 | R18: 5284183.5 | S18: =+Q18/$R$23 -> 0.018269459 | T18: 4630498.1 | U18: 4282387 | V18: 5509308.4 | W18: 4425416.2 | X18: 5107018.3 | Y18: 4130054.9
J19: Blanco | K19: =+L19/$M$23 -> 0.0097547312 | L19: 2548815.4 | M19: 4759470.3 | N19: 3666350.3 | O19: 2537019.4 | P19: 3438354.6 | Q19: 3373882.8 | R19: 2985786.5 | S19: =+Q19/$R$23 -> 0.013532356 | T19: 3848829.3 | U19: 3081180 | V19: 3223255 | W19: 3064804.3 | X19: 3282422 | Y19: 3299447.4
J20: Castillos | K20: =+L20/$M$23 -> 0.010328344 | L20: 2698694.8 | M20: 2475521.5 | N20: 1731015.2 | O20: 2325466.5 | P20: 2418879 | Q20: 4002278.5 | R20: 3017771.5 | S20: =+Q20/$R$23 -> 0.016052798 | T20: 3362112.3
J21: Asfalto | K21: =+L21/$M$23 -> 0.0057921566 | L21: 1513433.6 | M21: 2344115.2 | N21: 912612 | O21: 683890 | P21: 682752 | Q21: 2026664 | R21: 3880307.2 | S21: =+Q21/$R$23 -> 0.0081287766 | T21: 2344115.2 | U21: 773786 | V21: 193446.4 | W21: 568960 | Y21: 0
J22: Mezclas Secas | K22: =+L22/$M$23 -> 0.0056282493 | L22: 1470606.3 | M22: 1608122 | N22: 124119.08 | O22: 1876379.1 | P22: 1129370.2 | Q22: 1056975 | R22: 1596270.1 | S22: =+Q22/$R$23 -> 0.0042394366 | T22: 1475761.6 | U22: =1704059+233341 -> 1937400 | V22: 1871256.1 | W22: 1046331.7 | X22: 851322.78 | Y22: 1612656.2
J23: Grand Total | K23: =+L23/$N$23 -> 0.93604083 | L23: =SUM(L15:L22) -> 2.334054e+08 | M23: =SUM(M15:M22) -> 2.6129018e+08 | N23: =SUM(N15:N22) -> 2.4935386e+08 | O23: =SUM(O15:O22) -> 2.3553951e+08 | P23: =SUM(P15:P22) -> 2.0858903e+08 | Q23: =SUM(Q15:Q22) -> 2.2302781e+08 | R23: =SUM(R15:R22) -> 2.4931968e+08 | S23: =+Q23/$Q$23 -> 1 | T23: =SUM(T15:T22) -> 2.3256934e+08 | U23: =SUM(U15:U22) -> 247555331 | V23: =SUM(V15:V22) -> 2.5936986e+08 | W23: 2.1410369e+08 | X23: 2.3425211e+08 | Y23: 2.2616663e+08
AB25: Producto | AC25: Sep'25 | AD25: vs MA | AE25: % vs MA | AF25: vs MMAA | AG25: % vs MMAA | AH25: Acum'25 | AI25: % vs Acum'24 | AJ25: % vs Acum'23 | AK25: % vs Acum'22 | AL25: Conc. Acum'25
AB26: Gris Sacos | AC26: 44862.885 | AD26: -3523.804 | AE26: -0.072825896 | AF26: 1538.337 | AG26: 0.035507283 | AH26: 412255.99 | AI26: -0.0019112329 | AJ26: 0.047972848 | AK26: 0.066029138 | AL26: 0.073872278
AB27: Mortero | AC27: 8082.15 | AD27: -1638.95 | AE27: -0.16859718 | AF27: 885.675 | AG27: 0.12307067 | AH27: 78551.575 | AI27: 0.054215166 | AJ27: 0.036542436 | AK27: 0.066411751 | AL27: 0.073252035
AB28: Multiplast | AC28: 1339.66 | AD28: -104 | AE28: -0.072039123 | AF28: 122.26 | AG28: 0.10042714 | AH28: 12017.48 | AI28: 0.33316175 | AJ28: 0.22693827 | AK28: 0.20554063 | AL28: 0.086993797
AB29: Blanco | AC29: 475.975 | AD29: 83.65 | AE29: 0.21321608 | AF29: -36.1 | AG29: -0.070497486 | AH29: 3655.45 | AI29: -0.21729867 | AJ29: -0.25633462 | AK29: -0.14362589 | AL29: 0.050114526
AB30: Mezclas Secas | AC30: 511 | AD30: =+AC30-702 -> -191 | AE30: =(511/702)-1 -> -0.27207977 | AF30: =511-594 -> -83 | AG30: =(511/594)-1 -> -0.13973064 | AH30: 4770 | AI30: =(4770/4413)-1 -> 0.080897349 | AJ30: =(4770/1919)-1 -> 1.4856696 | AK30: =(4770/1283)-1 -> 2.7178488 | AL30: =511/(511+48) -> 0.91413238
AB31: 2 KG | AC31: 53.5 | AD31: 33.6 | AE31: 1.6884422 | AF31: 32.5 | AG31: 1.547619 | AH31: 275.9 | AI31: 0.14386401 | AJ31: -0.13410539 | AK31: 0.12437851 | AL31: 0.6487116

Sheet PROD REGION
B8: VOLUMEN NACIONAL | L8: Manual
B9: Producto | C9: Abr' | D9: vs MA | E9: % vs MA | F9: vs MMAA | G9: % vs MMAA | H9: Acum'26 | I9: % vs Acum'25 | J9: % vs Acum'24 | K9: % vs Acum'23 | L9: MMAA | M9: NOTA:
B10: Gris Sacos | C10: 42082.16 | D10: -7145.969 | E10: -0.14516028 | F10: 0 | G10: 0 | H10: 183727.92 | I10: 0.034688568 | J10: -0.0050721515 | K10: 0.087565655 | L10: 42082.16 | M10: tamaño de ancho 21 en las celdas
B11: 2 KG | C11: 46 | D11: 36.9 | E11: 4.0549451 | F11: 0 | G11: 0 | H11: 128.4 | I11: 0.2 | J11: -0.087809037 | K11: -0.10691929 | L11: 46
B12: Antihumedad | C12: 1382.6 | D12: -35.375 | E12: -0.024947548 | F12: 0 | G12: 0 | H12: 4977.6 | I12: 0.5737083 | L12: 1382.6
B13: Blanco | C13: 277.35 | D13: -310.2 | E13: -0.52795507 | F13: 0 | G13: 0 | H13: 1627.35 | I13: 0.018717331 | J13: -0.2982406 | K13: -0.18550433 | L13: 277.35
B14: Mortero | C14: 7333.15 | D14: -1436.45 | E14: -0.1637988 | F14: 0 | G14: 0 | H14: 34397.375 | I14: -0.0013797398 | J14: 0.035583342 | K14: 0.052524952 | L14: 7333.15
B15: Multiplast | C15: 1115.1 | D15: -80.95 | E15: -0.067681117 | F15: 0 | G15: 0 | H15: 4470.32 | I15: -0.1492656 | J15: 0.35206013 | K15: 0.093199464 | L15: 1115.1
B16: Mezclas Secas | C16: 486 | D16: -91.8 | E16: -0.1588785 | F16: 0 | G16: 0 | H16: 1830.6 | I16: -0.14465938 | J16: 0.27165775 | K16: 2.0666285 | L16: 486
B20: 106 px | C20: 76 px
B21: VOLUMEN REGIONAL | S21: Manual
B22: Región | C22: No. Tiendas | D22: Prom Acum Tienda | E22: Vol MA | F22: Vol MAct | G22: % vs MA | H22: % vs MMAA | I22: PD MA | J22: PD Mact | K22: % PD vs MA | L22: % PD vs MMAA | M22: Acum'25 | N22: Acum'26 | O22: Ac'26 vs '25 | P22: % '26 vs '25 | Q22: PD Acum'26 | R22: % PD '26 vs '25 | S22: Ratio AH/Gris Acum
B23: PACIFICO | C23: 39 | D23: 77.330128 | E23: 3271.85 | F23: 2600.825 | G23: -0.20509039 | H23: 0 | I23: 130.874 | J23: 108.36771 | K23: -0.17196916 | L23: 0 | M23: 12528.65 | N23: 12063.5 | O23: -465.15 | P23: -0.037126905 | Q23: 502.64583 | R23: -0.037126905 | S23: 0.26632705
B24: CENTRO-SUR | C24: 53 | D24: 72.049292 | E24: 3819.8 | F24: 3181.475 | G24: -0.16710953 | H24: 0 | I24: 152.792 | J24: 132.56146 | K24: -0.13240577 | L24: 0 | M24: 15114.9 | N24: 15274.45 | O24: 159.55 | P24: 0.010555809 | Q24: 636.43542 | R24: 0.010555809 | S24: 0.10526222
B25: NORTE - BAJIO | C25: 44 | D25: 39.962642 | E25: 1677.95 | F25: 1524.85 | G25: -0.09124229 | H25: 0 | I25: 67.118 | J25: 63.535417 | K25: -0.053377385 | L25: 0 | M25: 6801.35 | N25: 7033.425 | O25: 232.075 | P25: 0.034121902 | Q25: 293.05937 | R25: 0.034121902 | S25: 0.25159073
B26: NACIONAL | C26: 136 | D26: 63.182675 | E26: 8769.6 | F26: 7307.15 | G26: -0.16676359 | H26: 0 | I26: 350.784 | J26: 304.46458 | K26: -0.13204541 | L26: 0 | M26: 34444.9 | N26: 34371.375 | O26: -73.525 | P26: -0.0021345685 | Q26: 1432.1406 | R26: -0.0021345685 | S26: 0.10911278
B33: VOLUMEN REGIONAL
B43: Row Labels | C43: Acum'25 | D43: Acum'26
B44: CENTRO-SUR | C44: 11601 | D44: 8515
B45: NORTE - BAJIO | C45: 33562 | D45: 44890
B46: PACIFICO | C46: 29389 | D46: 13887
B47: Nacional | C47: 74552 | D47: 67292
B51: VOLUMEN NACIONAL
B53: Row Labels | C53: Acum'25 | D53: Acum'26
B54: (blank) | C54: 480
B55: CENTRO-SUR | C55: 11601 | D55: 8515
B56: NORTE - BAJIO | C56: 33562 | D56: 44890
B57: PACIFICO | C57: 29389 | D57: 13887
B58: Nacional | C58: 75032 | D58: 67292
B61: NOTA:
B62: copiar y pegar grafica de arriba como valor

Sheet CASTILLOS REGION
F2: Producto | G2: MAct | H2: MA | I2: % vs MA | J2: % vs MMAA | K2: Acum'26 | L2: Acum'25 | M2: Ac'26 vs '25 | N2: % '26 vs '25 | P2: 45 Pixeles, tamaño columna
F3: NORTE - BAJIO | G3: 9971 | H3: 10972 | I3: -0.091232227 | J3: 0 | K3: 44890 | L3: 33562 | M3: 11328 | N3: 0.33752458
F4: PACIFICO | G4: 6792 | H4: 2417 | I4: 1.8100952 | J4: 0 | K4: 13887 | L4: 29389 | M4: -15502 | N4: -0.52747627
F5: CENTRO-SUR | G5: 4359 | H5: 312 | I5: 12.971154 | J5: 0 | K5: 8515 | L5: 11601 | M5: -3086 | N5: -0.26601155
F6: (blank) | L6: 480 | M6: -480 | N6: -1
F7: NACIONAL | G7: 21122 | H7: 13701 | I7: 0.5416393 | J7: 0 | K7: 67292 | L7: 75032 | M7: -7740 | N7: -0.10315599
B12: NOTA: revisar la ultima fila de total en base de Marco

Sheet PROD PLAZA
B10: Gerencia | C10: Plaza | D10: No. Tiendas | E10: Prom Acum Tienda | F10: Ratio: vs Gris | G10: Vol MA | H10: Vol MAct | I10: % vs MA | J10: % vs MMAA | K10: Acum'26 | L10: Acum'25 | M10: Ac'26 vs '25 | N10: % '26 vs '25 | O10: Ratio: vs Gris Acum
B11: PENINSULA | C11: CAMPECHE | D11: 1 | E11: 4.525 | F11: 0.010649351 | G11: 12 | H11: 4.1 | I11: -0.65833333 | J11: 0 | K11: 18.1 | L11: 11.7 | M11: 6.4 | N11: 0.54700855 | O11: 0.0089792786
C12: CANCUN | D12: 2 | E12: 4.1125 | F12: 0.01741573 | G12: 14.2 | H12: 12.4 | I12: -0.12676056 | J12: 0 | K12: 32.9 | L12: 57.08 | M12: -24.18 | N12: -0.42361598 | O12: 0.01873933
C13: CD DEL CARMEN | D13: 1 | E13: 5.65 | F13: 0.024137931 | G13: 4 | H13: 4.2 | I13: 0.05 | J13: 0 | K13: 22.6 | L13: 12.9 | M13: 9.7 | N13: 0.75193798 | O13: 0.017385445
C14: CHETUMAL | D14: 1 | E14: 5.05 | F14: 0.021105528 | G14: 4 | H14: 4.2 | I14: 0.05 | J14: 0 | K14: 20.2 | L14: 8.58 | M14: 11.62 | N14: 1.3543124 | O14: 0.0072222222
C15: MERIDA | D15: 2 | E15: 6.45 | F15: 0.018447837 | G15: 18 | H15: 14.5 | I15: -0.19444444 | J15: 0 | K15: 51.6 | L15: 42.02 | M15: 9.58 | N15: 0.22798667 | O15: 0.010408719
C16: PLAYA DEL CARMEN | D16: 1 | E16: 2.9375 | F16: 0.023737374 | G16: 4.6 | H16: 7.05 | I16: 0.5326087 | J16: 0 | K16: 11.75 | L16: 0.5 | M16: 11.25 | N16: 22.5 | O16: 0.00044762757
B17: PENINSULA Total | D17: 8 | E17: 4.9109375 | F17: 0.018187157 | G17: 56.8 | H17: 46.45 | I17: -0.18221831 | J17: 0 | K17: 157.15 | L17: 132.78 | M17: 24.37 | N17: 0.18353668 | O17: 0.011610703
B18: SUR VER-TAB | C18: COATZACOALCOS | D18: 1 | E18: 31.15 | F18: 0.19310345 | G18: 4.2 | H18: 50.4 | I18: 11 | J18: 0 | K18: 124.6 | L18: 25.88 | M18: 98.72 | N18: 3.8145286 | O18: 0.022582897
C19: CORDOBA | D19: 1 | E19: 15.5 | F19: 0.065420561 | G19: 12 | H19: 14 | I19: 0.16666667 | J19: 0 | K19: 62 | L19: 68.4 | M19: -6.4 | N19: -0.093567251 | O19: 0.094736842
C20: VERACRUZ | D20: 1 | E20: 9.025 | F20: 0.011614731 | G20: 14 | H20: 4.1 | I20: -0.70714286 | J20: 0 | K20: 36.1 | L20: 48.1 | M20: -12 | N20: -0.24948025 | O20: 0.029875776
C21: VILLAHERMOSA | D21: 1 | E21: 6.0875 | F21: 0.033166667 | G21: 5 | H21: 9.95 | I21: 0.99 | J21: 0 | K21: 24.35 | L21: 36.06 | M21: -11.71 | N21: -0.32473655 | O21: 0.036946721
C22: XALAPA | D22: 1 | E22: 4.55 | F22: 0 | G22: 12 | H22: 0 | I22: -1 | J22: 0 | K22: 18.2 | L22: 21.3 | M22: -3.1 | N22: -0.14553991 | O22: 0.014411367
B23: SUR VER-TAB Total | D23: 5 | E23: 13.2625 | F23: 0.069424779 | G23: 47.2 | H23: 78.45 | I23: 0.66207627 | J23: 0 | K23: 265.25 | L23: 199.74 | M23: 65.51 | N23: 0.32797637 | O23: 0.033660263
B24: ESTADO DE MEXICO | C24: METEPEC & TOLUCA | D24: 2 | E24: 8.45 | F24: 0.026160338 | G24: 19 | H24: 18.6 | I24: -0.021052632 | J24: 0 | K24: 67.6 | L24: 72.58 | M24: -4.98 | N24: -0.068613943 | O24: 0.025070812
B25: ESTADO DE MEXICO Total | D25: 2 | E25: 8.45 | F25: 0.026160338 | G25: 19 | H25: 18.6 | I25: -0.021052632 | J25: 0 | K25: 67.6 | L25: 72.58 | M25: -4.98 | N25: -0.068613943 | O25: 0.025070812
B26: METRO-HIDALGO | C26: DF | D26: 25 | E26: 8.2549 | F26: 0.026207647 | G26: 234.475 | H26: 192.6 | I26: -0.17859047 | J26: 0 | K26: 825.49 | L26: 1037.56 | M26: -212.07 | N26: -0.204393 | O26: 0.032170408
C27: PACHUCA | D27: 1 | E27: 6.025 | F27: 0.013300493 | G27: 4 | H27: 8.1 | I27: 1.025 | J27: 0 | K27: 24.1 | L27: 28.3 | M27: -4.2 | N27: -0.14840989 | O27: 0.0091853294
B28: METRO-HIDALGO Total | D28: 26 | E28: 8.1691346 | F28: 0.025219904 | G28: 238.475 | H28: 200.7 | I28: -0.15840235 | J28: 0 | K28: 849.59 | L28: 1065.86 | M28: -216.27 | N28: -0.20290657 | O28: 0.03016528
B29: OAXACA - CHIAPAS | C29: OAXACA | D29: 1 | E29: 19.6 | F29: 0.029595588 | G29: 14 | H29: 16.1 | I29: 0.15 | J29: 0 | K29: 78.4 | L29: 169.3 | M29: -90.9 | N29: -0.53691672 | O29: 0.11123522
C30: TAPACHULA | D30: 1 | E30: 17.5075 | F30: 0.062837838 | G30: 12 | H30: 13.95 | I30: 0.1625 | J30: 0 | K30: 70.03 | L30: 130.8 | M30: -60.77 | N30: -0.46460245 | O30: 0.1244529
C31: TUXTLA | D31: 1 | E31: 30.55 | F31: 0.02413273 | G31: 24 | H31: 16 | I31: -0.33333333 | J31: 0 | K31: 122.2 | L31: 222.22 | M31: -100.02 | N31: -0.4500945 | O31: 0.070590851
B32: OAXACA - CHIAPAS Total | D32: 3 | E32: 22.5525 | F32: 0.032202797 | G32: 50 | H32: 46.05 | I32: -0.079 | J32: 0 | K32: 270.63 | L32: 522.32 | M32: -251.69 | N32: -0.48186935 | O32: 0.091298724
B33: PUE-TLAX-MOR | C33: CUAUTLA | D33: 1 | E33: 9.05 | F33: 0.017134831 | G33: 12 | H33: 12.2 | I33: 0.016666667 | J33: 0 | K33: 36.2 | L33: 62 | M33: -25.8 | N33: -0.41612903 | O33: 0.01711289
C34: CUERNAVACA | D34: 2 | E34: 13.159375 | F34: 0.034222661 | G34: 28 | H34: 25.975 | I34: -0.072321429 | J34: 0 | K34: 105.275 | L34: 182.66 | M34: -77.385 | N34: -0.42365597 | O34: 0.05955657
C35: PUEBLA | D35: 4 | E35: 8.455625 | F35: 0.020391325 | G35: 27 | H35: 43.25 | I35: 0.60185185 | J35: 0 | K35: 135.29 | L35: 169.04 | M35: -33.75 | N35: -0.19965689 | O35: 0.017711651
C36: TEHUACAN | D36: 1 | E36: 15.8 | F36: 0.026737968 | G36: 20 | H36: 10 | I36: -0.5 | J36: 0 | K36: 63.2 | L36: 78.2 | M36: -15 | N36: -0.19181586 | O36: 0.029598789
C37: TLAXCALA | D37: 1 | E37: 10.55 | F37: 0.018547141 | G37: 0 | H37: 12 | I37: 0 | J37: 0 | K37: 42.2 | L37: 43.26 | M37: -1.06 | N37: -0.024503005 | O37: 0.011369251
B38: PUE-TLAX-MOR Total | D38: 9 | E38: 10.615694 | F38: 0.022410618 | G38: 87 | H38: 103.425 | I38: 0.1887931 | J38: 0 | K38: 382.165 | L38: 535.16 | M38: -152.995 | N38: -0.28588646 | O38: 0.023592999
B39: TOTAL | D39: 53 | E39: 9.3980425 | F39: 0.026828705 | G39: 498.475 | H39: 493.675 | I39: -0.0096293696 | J39: 0 | K39: 1992.385 | L39: 2528.44 | M39: -536.055 | N39: -0.21201017 | O39: 0.030099043

Sheet CASTILLOS PLAZA
B9: Gerencia | C9: Plaza | D9: Vol. MA | E9: Vol. MAct | F9: % vs MA | G9: MMAA | H9: % vs MMAA | I9: Acum'26 | J9: Acum'25 | K9: Ac'26 vs '25 | L9: % '26 vs '25
B10: COAHUILA-DURANGO | D10: 19.75 | E10: 7.15 | F10: -0.63797468 | G10: 7.15 | H10: 0 | I10: 51.85 | J10: 38.05 | K10: 13.8 | L10: 0.36268068
C11: DURANGO | D11: 0 | E11: 4.5 | F11: 0 | G11: 4.5 | H11: 0 | I11: 6.75 | J11: 2.45 | K11: 4.3 | L11: 1.755102
C12: MONCLOVA | D12: 6.75 | E12: 0 | F12: -1 | G12: 0 | H12: 0 | I12: 15.95 | J12: 9.1 | K12: 6.85 | L12: 0.75274725
C13: PIEDRAS NEGRAS | D13: 4.5 | E13: 0.1 | F13: -0.97777778 | G13: 0.1 | H13: 0 | I13: 9.1 | J13: 13.35 | K13: -4.25 | L13: -0.31835206
C14: SALTILLO | D14: 4.5 | E14: 2.55 | F14: -0.43333333 | G14: 2.55 | H14: 0 | I14: 11.85 | J14: 2.4 | K14: 9.45 | L14: 3.9375
C15: TORREON | D15: 4 | E15: 0 | F15: -1 | G15: 0 | H15: 0 | I15: 8.2 | J15: 10.75 | K15: -2.55 | L15: -0.2372093
B16: ESTADO DE MEXICO | D16: 4.5 | E16: 4.5 | F16: 0 | G16: 4.5 | H16: 0 | I16: 19.6 | J16: 9.2 | K16: 10.4 | L16: 1.1304348
C17: METEPEC & TOLUCA | D17: 4.5 | E17: 4.5 | F17: 0 | G17: 4.5 | H17: 0 | I17: 19.6 | J17: 9.2 | K17: 10.4 | L17: 1.1304348
B18: GTO-QRO | D18: 18.45 | E18: 34.7 | F18: 0.88075881 | G18: 34.7 | H18: 0 | I18: 116.9 | J18: 171.925 | K18: -55.025 | L18: -0.32005235
C19: CELAYA | D19: 12 | E19: 0 | F19: -1 | G19: 0 | H19: 0 | I19: 14.1 | J19: 4.6 | K19: 9.5 | L19: 2.0652174
C20: IRAPUATO | D20: 0 | E20: 2.25 | F20: 0 | G20: 2.25 | H20: 0 | I20: 2.45 | J20: 4.5 | K20: -2.05 | L20: -0.45555556
C21: LEON | D21: 2.25 | E21: 18.2 | F21: 7.0888889 | G21: 18.2 | H21: 0 | I21: 59.2 | J21: 117.35 | K21: -58.15 | L21: -0.4955262
C22: QUERETARO | D22: 4.2 | E22: 12 | F22: 1.8571429 | G22: 12 | H22: 0 | I22: 34.7 | J22: 43.375 | K22: -8.675 | L22: -0.2
C23: SALAMANCA | D23: 0 | E23: 2.25 | F23: 0 | G23: 2.25 | H23: 0 | I23: 2.45 | J23: 0.1 | K23: 2.35 | L23: 23.5
C24: SAN JUAN | D24: 0 | E24: 0 | F24: 0 | G24: 0 | H24: 0 | I24: 4 | J24: 2 | K24: 2 | L24: 1
B25: GUERRERO | D25: 26.5 | E25: 28.5 | F25: 0.075471698 | G25: 28.5 | H25: 0 | I25: 103.975 | J25: 138.6 | K25: -34.625 | L25: -0.24981962
C26: ACAPULCO | D26: 26.5 | E26: 28.5 | F26: 0.075471698 | G26: 28.5 | H26: 0 | I26: 103.975 | J26: 138.6 | K26: -34.625 | L26: -0.24981962
B27: JALISCO - COLIMA | D27: 65.3 | E27: 12 | F27: -0.81623277 | G27: 12 | H27: 0 | I27: 147.325 | J27: 83.9 | K27: 63.425 | L27: 0.75595948
C28: COLIMA | D28: 8 | E28: 0 | F28: -1 | G28: 0 | H28: 0 | I28: 8.2 | J28: 2.2 | K28: 6 | L28: 2.7272727
C29: GUADALAJARA | D29: 26.1 | E29: 7 | F29: -0.73180077 | G29: 7 | H29: 0 | I29: 58.6 | J29: 57.3 | K29: 1.3 | L29: 0.022687609
C30: MANZANILLO | D30: 6 | E30: 0 | F30: -1 | G30: 0 | H30: 0 | I30: 10 | J30: 6.3 | K30: 3.7 | L30: 0.58730159
C31: PUERTO VALLARTA | D31: 25.2 | E31: 5 | F31: -0.8015873 | G31: 5 | H31: 0 | I31: 70.525 | J31: 18.1 | K31: 52.425 | L31: 2.8964088
B32: LAS CALIFORNIAS | D32: 47.4 | E32: 30.3 | F32: -0.36075949 | G32: 30.3 | H32: 0 | I32: 139.6 | J32: 171 | K32: -31.4 | L32: -0.18362573
C33: CABOS | D33: 10.1 | E33: 8 | F33: -0.20792079 | G33: 8 | H33: 0 | I33: 30.4 | J33: 78 | K33: -47.6 | L33: -0.61025641
C34: ENSENADA | D34: 6 | E34: 0 | F34: -1 | G34: 0 | H34: 0 | I34: 10.1 | J34: 8.2 | K34: 1.9 | L34: 0.23170732
C35: LA PAZ | D35: 4.1 | E35: 8 | F35: 0.95121951 | G35: 8 | H35: 0 | I35: 32.2 | J35: 32.2 | K35: 0 | L35: 0
C36: MEXICALI | D36: 12 | E36: 2.1 | F36: -0.825 | G36: 2.1 | H36: 0 | I36: 24.2 | J36: 24.5 | K36: -0.3 | L36: -0.012244898
C37: ROSARITO | D37: 0 | E37: 4 | F37: 0 | G37: 4 | H37: 0 | I37: 6 | J37: 4.2 | K37: 1.8 | L37: 0.42857143
C38: TIJUANA | D38: 15.2 | E38: 8.2 | F38: -0.46052632 | G38: 8.2 | H38: 0 | I38: 36.7 | J38: 23.9 | K38: 12.8 | L38: 0.53556485
B39: METRO-HIDALGO | D39: 106.375 | E39: 26 | F39: -0.75558167 | G39: 26 | H39: 0 | I39: 262.375 | J39: 184.7 | K39: 77.675 | L39: 0.42054683
C40: DF | D40: 102.375 | E40: 25.8 | F40: -0.74798535 | G40: 25.8 | H40: 0 | I40: 254.175 | J40: 182.5 | K40: 71.675 | L40: 0.39273973
C41: PACHUCA | D41: 4 | E41: 0.2 | F41: -0.95 | G41: 0.2 | H41: 0 | I41: 8.2 | J41: 2.2 | K41: 6 | L41: 2.7272727
B42: MICHOACAN | D42: 21.5 | E42: 4.5 | F42: -0.79069767 | G42: 4.5 | H42: 0 | I42: 30.35 | J42: 9.35 | K42: 21 | L42: 2.2459893
C43: MORELIA | D43: 13.5 | E43: 4.5 | F43: -0.66666667 | G43: 4.5 | H43: 0 | I43: 20.35 | J43: 7.15 | K43: 13.2 | L43: 1.8461538
C44: URUAPAN | D44: 4 | E44: 0 | F44: -1 | G44: 0 | H44: 0 | I44: 6 | J44: 0.1 | K44: 5.9 | L44: 59
C45: ZAMORA | D45: 4 | E45: 0 | F45: -1 | G45: 0 | H45: 0 | I45: 4 | J45: 2.1 | K45: 1.9 | L45: 0.9047619
B46: NUEVO LEON | D46: 42.3 | E46: 14 | F46: -0.66903073 | G46: 14 | H46: 0 | I46: 179 | J46: 74.9 | K46: 104.1 | L46: 1.3898531
C47: MTY | D47: 42.3 | E47: 14 | F47: -0.66903073 | G47: 14 | H47: 0 | I47: 179 | J47: 74.9 | K47: 104.1 | L47: 1.3898531
B48: OAXACA - CHIAPAS | D48: 13.95 | E48: 8.5 | F48: -0.390681 | G48: 8.5 | H48: 0 | I48: 30.5 | J48: 28.375 | K48: 2.125 | L48: 0.074889868
...

Sheet CEMEX GO Nuevo
B2: Región | C2: Dic'21 | D2: Ene'22 | E2: Feb'22 | F2: Mar'22 | G2: Abr'22 | H2: May'22 | I2: Jun'22 | J2: Jul'22 | K2: Ago'22 | L2: Sep'22 | M2: Oct'22 | N2: Nov'22 | O2: Dic'22 | P2: Ene'23 | Q2: Feb'23 | R2: Mar'23 | S2: Abr'23 | T2: May'23 | U2: Jun'23 | V2: Jul'23 | W2: Ago'23 | X2: Sep'23 | Y2: Oct'23 | Z2: Nov'23 | AA2: Dic'23 | AB2: Ene'24 | AC2: Feb'24 | AD2: Mar'24 | AE2: Abr'24 | AF2: May'24 | AG2: Jun'24 | AH2: Jul'24 | AI2: Ago'24 | AJ2: Sep'24 | AK2: Oct'24 | AL2: Nov'24 | AM2: Dic'24 | AN2: Ene'25 | AO2: Feb'25 | AP2: Mar'25 | AQ2: Abr'25 | AR2: May'25 | AS2: Jun'25 | AT2: Jul'25 | AU2: Ago'25 | AV2: Sep'25 | AW2: Oct'25 | AX2: Nov'25 | AY2: Dic'25 | AZ2: Ene'26 | BA2: Feb'26 | BB2: Mar'26 | BC2: Abr'26 | BF2: %
B3: Norte-Bajío | BB3: 0.659 | BE3: % Vs MA | BF3: =(BC3-BB3) -> -0.659
B4: Pacífico | BB4: 0.566 | BE4: % Vs MA | BF4: =BC4-BB4 -> -0.566
B5: Centro-Sur | BB5: 0.44 | BE5: % Vs MA | BF5: =(BC5-BB5) -> -0.44
BF7: %
C8: Dic'21 | D8: Ene'22 | E8: Feb'22 | F8: Mar'22 | G8: Abr'22 | H8: May'22 | I8: Jun'22 | J8: Jul'22 | K8: Ago'22 | L8: Sep'22 | M8: Oct'22 | N8: Nov'22 | O8: Dic'22 | P8: Ene'23 | Q8: Feb'23 | R8: Mar'23 | S8: Abr'23 | T8: May'23 | U8: Jun'23 | V8: Jul'23 | W8: Ago'23 | X8: Sep'23 | Y8: Oct'23 | Z8: Nov'23 | AA8: Dic'23 | AB8: Ene'24 | AC8: Feb'24 | AD8: Mar'24 | AE8: Abr'24 | AF8: May'24 | AG8: Jun'24 | AH8: Jul'24 | AI8: Ago'24 | AJ8: Sep'24 | AK8: Oct'24 | AL8: Nov'24 | AM8: Dic'24 | AN8: Ene'25 | AO8: Feb'25 | AP8: Mar'25 | AQ8: Abr'25 | AR8: May'25 | AS8: Jun'25 | AT8: Jul'25 | AU8: Ago'25 | AV8: Sep'25 | AW8: Oct'25 | AX8: Nov'25 | AY8: Dic'25 | AZ8: Ene'26 | BA8: Feb'26 | BB8: Mar'26 | BC8: Abr'26 | BE8: % MAct
B9: Nacional | C9: 0.3 | D9: 0.33 | E9: 0.4 | F9: 0.4 | G9: 0.4 | H9: 0.39 | I9: 0.42 | J9: 0.44 | K9: 0.45 | L9: 0.52 | M9: 0.5 | N9: 0.49 | O9: 0.49 | P9: 0.51 | Q9: 0.47 | R9: 0.53 | S9: 0.5 | T9: 0.52 | U9: 0.55 | V9: 0.51 | W9: 0.52 | X9: 0.52 | Y9: 0.52 | Z9: 0.54 | AA9: 0.54 | AB9: 0.53 | AC9: 0.56 | AD9: 0.58 | AE9: 0.64 | AF9: 0.63 | AG9: 0.61 | AH9: 0.65 | AI9: 0.64 | AJ9: 0.64 | AK9: 0.64 | AL9: 0.68 | AM9: 0.69 | AN9: 0.7 | AO9: 0.68 | AP9: 0.68 | AQ9: 0.66 | AR9: 0.68 | AS9: 0.7 | AT9: 0.63 | AU9: 0.59 | AV9: 0.61 | AW9: 0.58 | AX9: 0.562 | AY9: 0.553 | AZ9: 0.541 | BA9: 0.518 | BB9: 0.528 | BE9: % Vs MA | BF9: =(BC9-BB9) -> -0.528
BE10: % Vs Dic'21 | BF10: =(BC9-C9) -> -0.3

Sheet CEMEX GO
B2: Región | C2: Dic'21 | D2: Ene'22 | E2: Feb'22 | F2: Mar'22 | G2: Abr'22 | H2: May'22 | I2: Jun'22 | J2: Jul'22 | K2: Ago'22 | L2: Sep'22 | M2: Oct'22 | N2: Nov'22 | O2: Dic'22 | P2: Ene'23 | Q2: Feb'23 | R2: Mar'23 | S2: Abr'23 | T2: May'23 | U2: Jun'23 | V2: Jul'23 | W2: Ago'23 | X2: Sep'23 | Y2: Oct'23 | Z2: Nov'23 | AA2: Dic'23 | AB2: Ene'24 | AC2: Feb'24 | AD2: Mar'24 | AE2: Abr'24 | AF2: May'24 | AG2: Jun'24 | AH2: Jul'24 | AI2: Ago'24 | AJ2: Sep'24 | AK2: Oct'24 | AL2: Nov'24 | AM2: Dic'24 | AN2: Ene'25 | AO2: Feb'25 | AP2: Mar'25 | AQ2: Abr'25 | AR2: May'25 | AS2: Jun'25 | AT2: Jul'25 | AU2: Ago'25 | AV2: Sep'25 | AW2: Oct'25 | AX2: Nov'25 | AY2: Dic'25 | AZ2: Ene'26 | BA2: Feb'26 | BB2: Mar'26 | BC2: Abr'26 | BF2: %
B3: Pacífico | C3: 0.3 | D3: 0.34 | E3: 0.27 | F3: 0.3 | G3: 0.32 | H3: 0.25 | I3: 0.35 | J3: 0.42 | K3: 0.36 | L3: 0.41 | M3: 0.43 | N3: 0.37 | O3: 0.39 | P3: 0.41 | Q3: 0.37 | R3: 0.42 | S3: 0.39 | T3: 0.38 | U3: 0.39 | V3: 0.33 | W3: 0.44 | X3: 0.39 | Y3: 0.43 | Z3: 0.41 | AA3: 0.43 | AB3: 0.56 | AC3: 0.46 | AD3: 0.49 | AE3: 0.64 | AF3: 0.63 | AG3: 0.66 | AH3: 0.72 | AI3: 0.76 | AJ3: 0.71 | AK3: 0.71 | AL3: 0.78 | AM3: 0.77 | AN3: 0.75 | AO3: 0.76 | AP3: 0.76 | AQ3: 0.76 | AR3: 0.77 | AS3: 0.79 | AT3: 0.77 | AU3: 0.77 | AV3: 0.77 | AW3: 0.76 | AX3: 0.761 | AY3: 0.766 | AZ3: 0.736 | BA3: 0.706 | BE3: % Vs MA | BF3: =(BC3-BB3) -> 0
B4: Noreste | C4: 0.57 | D4: 0.54 | E4: 0.58 | F4: 0.56 | G4: 0.58 | H4: 0.53 | I4: 0.52 | J4: 0.59 | K4: 0.59 | L4: 0.75 | M4: 0.67 | N4: 0.71 | O4: 0.68 | P4: 0.69 | Q4: 0.64 | R4: 0.69 | S4: 0.66 | T4: 0.65 | U4: 0.66 | V4: 0.64 | W4: 0.61 | X4: 0.61 | Y4: 0.61 | Z4: 0.66 | AA4: 0.66 | AB4: 0.64 | AC4: 0.71 | AD4: 0.75 | AE4: 0.84 | AF4: 0.84 | AG4: 0.86 | AH4: 0.87 | AI4: 0.83 | AJ4: 0.86 | AK4: 0.83 | AL4: 0.87 | AM4: 0.88 | AN4: 0.87 | AO4: 0.86 | AP4: 0.87 | AQ4: 0.87 | AR4: 0.9 | AS4: 0.89 | AT4: 0.84 | AU4: 0.68 | AV4: 0.67 | AW4: 0.6 | AX4: 0.584 | AY4: 0.586 | AZ4: 0.601 | BA4: 0.559 | BE4: % Vs MA | BF4: =BC4-BB4 -> 0
B5: Centro | C5: 0.11 | D5: 0.21 | E5: 0.33 | F5: 0.33 | G5: 0.33 | H5: 0.39 | I5: 0.4 | J5: 0.36 | K5: 0.41 | L5: 0.43 | M5: 0.44 | N5: 0.42 | O5: 0.4 | P5: 0.42 | Q5: 0.41 | R5: 0.42 | S5: 0.36 | T5: 0.46 | U5: 0.53 | V5: 0.45 | W5: 0.44 | X5: 0.44 | Y5: 0.44 | Z5: 0.45 | AA5: 0.46 | AB5: 0.39 | AC5: 0.42 | AD5: 0.44 | AE5: 0.45 | AF5: 0.43 | AG5: 0.37 | AH5: 0.36 | AI5: 0.34 | AJ5: 0.34 | AK5: 0.34 | AL5: 0.36 | AM5: 0.37 | AN5: 0.48 | AO5: 0.42 | AP5: 0.39 | AQ5: 0.36 | AR5: 0.36 | AS5: 0.4 | AT5: 0.35 | AU5: 0.35 | AV5: 0.37 | AW5: 0.35 | AX5: 0.334 | AY5: 0.328 | AZ5: 0.3 | BA5: 0.302 | BE5: % Vs MA | BF5: =(BC5-BB5) -> 0
B6: Sureste | C6: 0.11 | D6: 0.17 | E6: 0.38 | F6: 0.36 | G6: 0.32 | H6: 0.33 | I6: 0.36 | J6: 0.35 | K6: 0.37 | L6: 0.44 | M6: 0.41 | N6: 0.44 | O6: 0.43 | P6: 0.47 | Q6: 0.43 | R6: 0.55 | S6: 0.63 | T6: 0.58 | U6: 0.61 | V6: 0.6 | W6: 0.63 | X6: 0.68 | Y6: 0.66 | Z6: 0.66 | AA6: 0.65 | AB6: 0.61 | AC6: 0.69 | AD6: 0.64 | AE6: 0.66 | AF6: 0.65 | AG6: 0.66 | AH6: 0.74 | AI6: 0.68 | AJ6: 0.7 | AK6: 0.68 | AL6: 0.69 | AM6: 0.75 | AN6: 0.69 | AO6: 0.71 | AP6: 0.72 | AQ6: 0.7 | AR6: 0.72 | AS6: 0.74 | AT6: 0.67 | AU6: 0.72 | AV6: 0.74 | AW6: 0.72 | AX6: 0.703 | AY6: 0.651 | AZ6: 0.646 | BA6: 0.633 | BE6: % Vs MA | BF6: =(BC6-BB6) -> 0
BF8: %
C9: Dic'21 | D9: Ene'22 | E9: Feb'22 | F9: Mar'22 | G9: Abr'22 | H9: May'22 | I9: Jun'22 | J9: Jul'22 | K9: Ago'22 | L9: Sep'22 | M9: Oct'22 | N9: Nov'22 | O9: Dic'22 | P9: Ene'23 | Q9: Feb'23 | R9: Mar'23 | S9: Abr'23 | T9: May'23 | U9: Jun'23 | V9: Jul'23 | W9: Ago'23 | X9: Sep'23 | Y9: Oct'23 | Z9: Nov'23 | AA9: Dic'23 | AB9: Ene'24 | AC9: Feb'24 | AD9: Mar'24 | AE9: Abr'24 | AF9: May'24 | AG9: Jun'24 | AH9: Jul'24 | AI9: Ago'24 | AJ9: Sep'24 | AK9: Oct'24 | AL9: Nov'24 | AM9: Dic'24 | AN9: Ene'25 | AO9: Feb'25 | AP9: Mar'25 | AQ9: Abr'25 | AR9: May'25 | AS9: Jun'25 | AT9: Jul'25 | AU9: Ago'25 | AV9: Sep'25 | AW9: Oct'25 | AX9: Nov'25 | AY9: Dic'25 | AZ9: Ene'26 | BA9: Feb'26 | BB9: Mar'26 | BC9: Abr'26 | BE9: % MAct
B10: Nacional | C10: 0.3 | D10: 0.33 | E10: 0.4 | F10: 0.4 | G10: 0.4 | H10: 0.39 | I10: 0.42 | J10: 0.44 | K10: 0.45 | L10: 0.52 | M10: 0.5 | N10: 0.49 | O10: 0.49 | P10: 0.51 | Q10: 0.47 | R10: 0.53 | S10: 0.5 | T10: 0.52 | U10: 0.55 | V10: 0.51 | W10: 0.52 | X10: 0.52 | Y10: 0.52 | Z10: 0.54 | AA10: 0.54 | AB10: 0.53 | AC10: 0.56 | AD10: 0.58 | AE10: 0.64 | AF10: 0.63 | AG10: 0.61 | AH10: 0.65 | AI10: 0.64 | AJ10: 0.64 | AK10: 0.64 | AL10: 0.68 | AM10: 0.69 | AN10: 0.7 | AO10: 0.68 | AP10: 0.68 | AQ10: 0.66 | AR10: 0.68 | AS10: 0.7 | AT10: 0.63 | AU10: 0.59 | AV10: 0.61 | AW10: 0.58 | AX10: 0.562 | AY10: 0.553 | AZ10: 0.541 | BA10: 0.518 | BE10: % Vs MA | BF10: =(BC10-BB10) -> 0
BE11: % Vs Dic'21 | BF11: =(BC10-C10) -> -0.3

Sheet Ventas MS, Antihu y Asfalt ANTE
B2: MEZCLAS
B3: Región | C3: No. Tiendas | D3: Tiendas con MS | E3: Vol SO MA | F3: Vol SO MAct | G3: % vs MA | H3: % vs MMAA | I3: Acum'25 | J3: Acum'26 | K3: Ac'26 vs '25 | L3: % '26 vs '25
B4: PACIFICO | C4: 34 | E4: 94 | G4: =IFERROR((F4-E4)/E4,0) -> -1 | H4: =(F4-148.125)/148.125 -> -1 | I4: =166.75+148.125 -> 314.875 | J4: =109.325+94 -> 203.325 | K4: =J4-I4 -> -111.55 | L4: =K4/I4 -> -0.35426757
B5: NORESTE | C5: 38 | E5: 181.875 | G5: =IFERROR((F5-E5)/E5,0) -> -1 | H5: =(F5-151.1)/151.1 -> -1 | I5: =151.15+151.1 -> 302.25 | J5: =162.675+181.875 -> 344.55 | K5: =J5-I5 -> 42.3 | L5: =K5/I5 -> 0.13995037
B6: CENTRO | C6: 43 | E6: 153.9 | G6: =IFERROR((F6-E6)/E6,0) -> -1 | H6: =(F6-129.075)/129.075 -> -1 | I6: =142.125+129.075 -> 271.2 | J6: =153.5+153.9 -> 307.4 | K6: =J6-I6 -> 36.2 | L6: =K6/I6 -> 0.13348083
B7: SURESTE | C7: 22 | E7: 49.15 | G7: =IFERROR((F7-E7)/E7,0) -> -1 | H7: =(F7-76.475)/76.475 -> -1 | I7: =74.75+76.475 -> 151.225 | J7: =61.125+49.15 -> 110.275 | K7: =J7-I7 -> -40.95 | L7: =K7/I7 -> -0.27078856
B8: NACIONAL | C8: =SUM(C4:C7) -> 137 | D8: =D4+D5+D6+D7 -> 0 | E8: =SUM(E4:E7) -> 478.925 | F8: =SUM(F4:F7) -> 0 | G8: =(F8-E8)/E8 -> -1 | H8: =(F8-534.775)/534.775 -> -1 | I8: =SUM(I4:I7) -> 1039.55 | J8: =SUM(J4:J7) -> 965.55 | K8: =J8-I8 -> -74 | L8: =K8/I8 -> -0.071184647
B11: Región | C11: No. Tiendas | D11: Tiendas con MS | E11: Vol SI MA | F11: Vol SI MAct | G11: % vs MA | H11: % vs MMAA | I11: Acum'25 | J11: Acum'26 | K11: Ac'26 vs '25 | L11: % '26 vs '25
B12: NACIONAL | C12: =SUM(C8:C11) -> 137 | D12: =SUM(D8:D11) -> 0 | E12: ='MS antes'!DE94 -> 93.6 | F12: ='MS antes'!DF94 -> 0 | G12: =(F12-E12)/E12 -> -1 | H12: =(F12-'MS antes'!CR94)/'MS antes'!CR94 -> -1 | I12: ='MS antes'!DC94 -> 1657.8 | J12: ='MS antes'!DP94 -> 766.8 | K12: =J12-I12 -> -891 | L12: =K12/I12 -> -0.53745928
B14: ANTIHUMEDAD PPT
B16: Región | C16: No. Tiendas | D16: Tiendas con Antihumedad | E16: Vol SI MAct | F16: Vol SO MAct
B17: PACIFICO | C17: 34
B18: NORESTE | C18: 38
B19: CENTRO | C19: 43
B20: SURESTE | C20: 22
B21: NACIONAL | C21: =SUM(C17:C20) -> 137 | D21: =SUM(D17:D20) -> 0 | E21: =SUM(E17:E20) -> 0 | F21: =SUM(F17:F20) -> 0
B24: ANTIHUMEDAD
B25: Región | C25: No. Tiendas | D25: Prom Mes Tienda | E25: Vol MA | F25: Vol MAct | G25: % vs MA | H25: % vs MMAA | I25: PD MA | J25: PD MAct | K25: % PD vs MA | L25: % PD vs MMAA | M25: Acum'25 | N25: Acum'26 | O25: Ac'26 vs '25 | P25: % '26 vs '25 | Q25: PD Acum'26 | R25: % PD '25 vs '25
B26: PACIFICO | C26: 34 | D26: =('ANTIHUMEDAD antes'!$AP$28/'Ventas MS, Antihu y Asfalt ANTE'!$C26)/3 -> 4.5727941 | E26: ='ANTIHUMEDAD antes'!$AE$28 -> 238.1 | F26: ='ANTIHUMEDAD antes'!$AF$28 -> 0 | G26: =(F26-E26)/E26 -> -1 | H26: =('ANTIHUMEDAD antes'!$AF$28-'ANTIHUMEDAD antes'!$S$28)/'ANTIHUMEDAD antes'!$S$28 -> -1 | I26: ='ANTIHUMEDAD antes'!$AE$28/'ANTIHUMEDAD antes'!$AE$2 -> 10.352174 | J26: ='ANTIHUMEDAD antes'!$AF$28/'ANTIHUMEDAD antes'!$AF$2 -> 0 | K26: =(J26-I26)/I26 -> -1 | L26: =(J26-('ANTIHUMEDAD antes'!$S$28/'ANTIHUMEDAD antes'!$S$2)/('ANTIHUMEDAD antes'!$S$28/'ANTIHUMEDAD antes'!$S$2)) -> -1 | M26: ='ANTIHUMEDAD antes'!$AC$28 -> 430.525 | N26: ='ANTIHUMEDAD antes'!$AP$28 -> 466.425 | O26: =N26-M26 -> 35.9 | P26: =O26/M26 -> 0.083386563 | Q26: ='ANTIHUMEDAD antes'!$AP$28/'ANTIHUMEDAD antes'!$AP$2 -> 6.3030405 | R26: =Q26-('ANTIHUMEDAD antes'!$AC$94/'ANTIHUMEDAD antes'!$AC$2)/('ANTIHUMEDAD antes'!$AC$94/'ANTIHUMEDAD antes'!$AC$2) -> 5.3030405
B27: NORESTE | C27: 38 | D27: =('ANTIHUMEDAD antes'!$AP$53/'Ventas MS, Antihu y Asfalt ANTE'!C27)/3 -> 4.1866228 | E27: ='ANTIHUMEDAD antes'!$AE$53 -> 304.825 | F27: ='ANTIHUMEDAD antes'!$AF$53 -> 0 | G27: =(F27-E27)/E27 -> -1 | H27: =('ANTIHUMEDAD antes'!$AF$53-'ANTIHUMEDAD antes'!$S$53)/'ANTIHUMEDAD antes'!$S$53 -> -1 | I27: ='ANTIHUMEDAD antes'!$AE$53/'ANTIHUMEDAD antes'!$AE$2 -> 13.253261 | J27: ='ANTIHUMEDAD antes'!$AF$53/'ANTIHUMEDAD antes'!$AF$2 -> 0 | K27: =(J27-I27)/I27 -> -1 | L27: =(J27-('ANTIHUMEDAD antes'!$S$53/'ANTIHUMEDAD antes'!$S$2)/('ANTIHUMEDAD antes'!$S$53/'ANTIHUMEDAD antes'!$S$2)) -> -1 | M27: ='ANTIHUMEDAD antes'!$AC$53 -> 546.725 | N27: ='ANTIHUMEDAD antes'!$AP$53 -> 477.275 | O27: =N27-M27 -> -69.45 | P27: =O27/M27 -> -0.12702913 | Q27: ='ANTIHUMEDAD antes'!$AP$53/'ANTIHUMEDAD antes'!$AP$2 -> 6.4496622 | R27: =Q27-('ANTIHUMEDAD antes'!$AC$94/'ANTIHUMEDAD antes'!$AC$2)/('ANTIHUMEDAD antes'!$AC$94/'ANTIHUMEDAD antes'!$AC$2) -> 5.4496622
B28: CENTRO | C28: 43 | D28: =('ANTIHUMEDAD antes'!$AP$70/'Ventas MS, Antihu y Asfalt ANTE'!C28)/3 -> 6.1625969 | E28: ='ANTIHUMEDAD antes'!$AE$70 -> 489.55 | F28: ='ANTIHUMEDAD antes'!$AF$70 -> 0 | G28: =(F28-E28)/E28 -> -1 | H28: =('ANTIHUMEDAD antes'!$AF$70-'ANTIHUMEDAD antes'!$S$70)/'ANTIHUMEDAD antes'!$S$70 -> -1 | I28: ='ANTIHUMEDAD antes'!$AE$70/'ANTIHUMEDAD antes'!$AE$2 -> 21.284783 | J28: ='ANTIHUMEDAD antes'!$AF$70/'ANTIHUMEDAD antes'!$AF$2 -> 0 | K28: =(J28-I28)/I28 -> -1 | L28: =(J28-('ANTIHUMEDAD antes'!$S$70/'ANTIHUMEDAD antes'!$S$2)/('ANTIHUMEDAD antes'!$S$70/'ANTIHUMEDAD antes'!$S$2)) -> -1 | M28: ='ANTIHUMEDAD antes'!$AC$70 -> 833.55 | N28: ='ANTIHUMEDAD antes'!$AP$70 -> 794.975 | O28: =N28-M28 -> -38.575 | P28: =O28/M28 -> -0.046277968 | Q28: ='ANTIHUMEDAD antes'!$AP$70/'ANTIHUMEDAD antes'!$AP$2 -> 10.742905 | R28: =Q28-('ANTIHUMEDAD antes'!$AC$94/'ANTIHUMEDAD antes'!$AC$2)/('ANTIHUMEDAD antes'!$AC$94/'ANTIHUMEDAD antes'!$AC$2) -> 9.7429054
B29: SURESTE | C29: 22 | D29: =('ANTIHUMEDAD antes'!$AP$93/'Ventas MS, Antihu y Asfalt ANTE'!C29)/3 -> 6.5522727 | E29: ='ANTIHUMEDAD antes'!$AE$93 -> 236.675 | F29: ='ANTIHUMEDAD antes'!$AF$93 -> 0 | G29: =(F29-E29)/E29 -> -1 | H29: =('ANTIHUMEDAD antes'!$AF$93-'ANTIHUMEDAD antes'!$S$93)/'ANTIHUMEDAD antes'!$S$93 -> -1 | I29: ='ANTIHUMEDAD antes'!$AE$93/'ANTIHUMEDAD antes'!$AE$2 -> 10.290217 | J29: ='ANTIHUMEDAD antes'!$AF$93/'ANTIHUMEDAD antes'!$AF$2 -> 0 | K29: =(J29-I29)/I29 -> -1 | L29: =(J29-('ANTIHUMEDAD antes'!$S$93/'ANTIHUMEDAD antes'!$S$2)/('ANTIHUMEDAD antes'!$S$93/'ANTIHUMEDAD antes'!$S$2)) -> -1 | M29: ='ANTIHUMEDAD antes'!$AC$93 -> 494.15 | N29: ='ANTIHUMEDAD antes'!$AP$93 -> 432.45 | O29: =N29-M29 -> -61.7 | P29: =O29/M29 -> -0.12486087 | Q29: ='ANTIHUMEDAD antes'!$AP$93/'ANTIHUMEDAD antes'!$AP$2 -> 5.8439189 | R29: =Q29-('ANTIHUMEDAD antes'!$AC$94/'ANTIHUMEDAD antes'!$AC$2)/('ANTIHUMEDAD antes'!$AC$94/'ANTIHUMEDAD antes'!$AC$2) -> 4.8439189
B30: NACIONAL | C30: =SUM(C26:C29) -> 137 | D30: =('ANTIHUMEDAD antes'!$AP$94/'Ventas MS, Antihu y Asfalt ANTE'!C30)/3 -> 5.2825426 | E30: ='ANTIHUMEDAD antes'!$AE$94 -> 1269.15 | F30: ='ANTIHUMEDAD antes'!$AF$94 -> 0 | G30: =(F30-E30)/E30 -> -1 | H30: =('ANTIHUMEDAD antes'!$AF$94-'ANTIHUMEDAD antes'!$S$94)/'ANTIHUMEDAD antes'!$S$94 -> -1 | I30: ='ANTIHUMEDAD antes'!$AE$94/'ANTIHUMEDAD antes'!$AE$2 -> 55.180435 | J30: ='ANTIHUMEDAD antes'!$AF$94/'ANTIHUMEDAD antes'!$AF$2 -> 0 | K30: =(J30-I30)/I30 -> -1 | L30: =(J30-('ANTIHUMEDAD antes'!$S$94/'ANTIHUMEDAD antes'!$S$2)/('ANTIHUMEDAD antes'!$S$94/'ANTIHUMEDAD antes'!$S$2)) -> -1 | M30: ='ANTIHUMEDAD antes'!$AC$94 -> 2304.95 | N30: ='ANTIHUMEDAD antes'!$AP$94 -> 2171.125 | O30: =N30-M30 -> -133.825 | P30: =O30/M30 -> -0.058059828 | Q30: ='ANTIHUMEDAD antes'!$AP$94/'ANTIHUMEDAD antes'!$AP$2 -> 29.339527 | R30: =Q30-('ANTIHUMEDAD antes'!AC94/'ANTIHUMEDAD antes'!AC2)/('ANTIHUMEDAD antes'!AC94/'ANTIHUMEDAD antes'!AC2) -> 28.339527
B33: ASFALTO | H33: No aplica | K33: No aplica | L33: No aplica
B34: Región | C34: No. Tiendas | D34: Tiendas con Asfalto | E34: Vol SO MA | F34: Vol SO MAct | G34: % vs MA | H34: % vs MMAA | I34: Acum'25 | J34: Acum'26 | K34: Ac'26 vs '25 | L34: % '26 vs '25
B35: PACIFICO | C35: 34 | E35: 54.625 | G35: =IFERROR((F35-E35)/E35,0) -> -1 | I35: =ASFALTO!$P$32 -> 0 | J35: =74.625+54.625 -> 129.25
B36: NORESTE | C36: 38 | E36: 85.7 | G36: =IFERROR((F36-E36)/E36,0) -> -1 | I36: =ASFALTO!$P$59 -> 0 | J36: =67.375+85.7 -> 153.075
B37: CENTRO | C37: 43 | E37: 118.05 | G37: =IFERROR((F37-E37)/E37,0) -> -1 | I37: =ASFALTO!#REF! -> #REF! | J37: =101.725+118.05 -> 219.775
B38: SURESTE | C38: 22 | E38: 42.875 | G38: =IFERROR((F38-E38)/E38,0) -> -1 | I38: =ASFALTO!$P$88 -> 0 | J38: =42.475+42.875 -> 85.35
B39: NACIONAL | C39: =SUM(C35:C38) -> 137 | D39: =D35+D36+D37+D38 -> 0 | E39: =SUM(E35:E38) -> 301.25 | F39: =SUM(F35:F38) -> 0 | G39: =(F39-E39)/E39 -> -1 | I39: =SUM(I35:I38) -> #REF! | J39: =SUM(J35:J38) -> 587.45
H41: No aplica | I41: No aplica | K41: No aplica | L41: No aplica
B42: Región | C42: No. Tiendas | D42: Tiendas con Asfalto | E42: Vol SI MA | F42: Vol SI MAct | G42: % vs MA | H42: % vs MMAA | I42: Acum'25 | J42: Acum'26 | K42: Ac'26 vs '25 | L42: % '26 vs '25
B43: NACIONAL | C43: =SUM(C39:C42) -> 137 | D43: =SUM(D39:D42) -> 0 | E43: =ASFALTO!$R$89 -> 250 | F43: =ASFALTO!$S$89 -> 440 | G43: =(F43-E43)/E43 -> 0.76 | I43: =ASFALTO!$P$89 -> 0 | J43: =ASFALTO!$AC$89 -> 1180 | K43: =J43-I43 -> 1180 | L43: =K43/I43 -> #DIV/0!
I90: =1126.725+143 -> 1269.725

Sheet GRAFICAS PRECIO
AF2: PRECIO NETO
AF3: Producto | AG3: $Mar'26 | AH3: $ vs MA | AI3: % vs MA | AJ3: $ vs MMAA | AK3: % vs MMAA | AL3: $ Acum'26 | AM3: $ vs Acum'25 | AN3: % vs Acum'25 | AO3: $Dic'25 | AP3: $ vs Dic'25 | AQ3: % vs Dic'25 | AR3: $ Utilidad TN (Acum'25) | AS3: % Utilidad TN (Acum'25)
AF4: Gris Saco | AG4: 4162.9246 | AH4: -20.783159 | AI4: -0.0049676411 | AJ4: 211.8878 | AK4: 0.053628406 | AL4: 4107.1278 | AM4: 174.85093 | AN4: 0.04446557 | AO4: 3861.0579 | AP4: =+AG4-AO4 -> 301.86669 | AQ4: =AP4/AO4 -> 0.078182377 | AR4: 2028.8484 | AS4: 0.51876033
AF5: Mortero | AG5: 3426.3783 | AH5: -60.588363 | AI5: -0.017375665 | AJ5: 218.79104 | AK5: 0.068210472 | AL5: 3372.3613 | AM5: 210.50489 | AN5: 0.066576359 | AO5: 3135.2614 | AP5: =+AG5-AO5 -> 291.11692 | AQ5: =AP5/AO5 -> 0.092852519 | AR5: 1722.5289 | AS5: 0.54548714
AF6: Blanco | AG6: 7887.8188 | AH6: -10.76003 | AI6: -0.0013622742 | AJ6: 137.74395 | AK6: 0.017773242 | AL6: 7804.5623 | AM6: 102.72824 | AN6: 0.013338153 | AO6: 7698.9991 | AP6: =+AG6-AO6 -> 188.81977 | AQ6: =AP6/AO6 -> 0.024525236 | AR6: 3916.8615 | AS6: 0.51217396
AF7: Multiplast | AG7: 4502.4758 | AH7: -137.03614 | AI7: -0.029536757 | AJ7: 30.308471 | AK7: 0.0067771327 | AL7: 4571.1522 | AM7: 176.70554 | AN7: 0.040211102 | AO7: 4476.5538 | AP7: =+AG7-AO7 -> 25.922054 | AQ7: =AP7/AO7 -> 0.0057906273 | AR7: 600.26429 | AS7: 0.13447147
AS9: Utilidad a NOV'25
B14: GRIS | R14: MORTERO
C15: E | D15: F | E15: M | F15: A | G15: M | H15: J | I15: J | J15: A | K15: S | L15: O | M15: N | N15: D | S15: E | T15: F | U15: M | V15: A | W15: M | X15: J | Y15: J | Z15: A | AA15: S | AB15: O | AC15: N | AD15: D
B16: 2021 | C16: 2741.0228 | D16: 2727.9688 | E16: 2742.0482 | F16: 2783.1918 | G16: 2775.0963 | H16: 2774.9258 | I16: 2850.9542 | J16: 2866.0135 | K16: 2881.406 | L16: 2864.6695 | M16: 2937.279 | N16: 2888.6484 | R16: 2021 | S16: 2184.2554 | T16: 2187.9322 | U16: 2185.6659 | V16: 2225.1266 | W16: 2208.0484 | X16: 2219.2326 | Y16: 2270.42 | Z16: 2286.2232 | AA16: 2297.4991 | AB16: 2285.8449 | AC16: 2343.5744 | AD16: 2319.6664
B17: 2022 | C17: 3071.2614 | D17: 3300.1758 | E17: 3231.7987 | F17: 3280.6624 | G17: 3429.8277 | H17: 3379.2273 | I17: 3482.3845 | J17: 3538.7882 | K17: 3423.8753 | L17: 3425 | M17: 3610.3399 | N17: 3489.3214 | R17: 2022 | S17: 2500.6184 | T17: 2693.3072 | U17: 2593.8938 | V17: 2619.0847 | W17: 2793.3114 | X17: 2735.3143 | Y17: 2807.3801 | Z17: 2834.405 | AA17: 2862.9617 | AB17: 2817 | AC17: 2945.0672 | AD17: 2811.4114
B18: 2023 | C18: 3698.5474 | D18: 3910.8892 | E18: 3806.3684 | F18: 3739 | G18: 3735 | H18: 3723 | I18: 3666 | J18: 3762 | K18: 3706 | L18: 3675 | M18: 3673.7184 | N18: 3620.8805 | R18: 2023 | S18: 2986.4954 | T18: 3194.428 | U18: 3050.6275 | V18: 3007 | W18: 3001 | X18: 2981 | Y18: 2969 | Z18: 3072 | AA18: 3000 | AB18: 2951.0826 | AC18: 2970.0855 | AD18: 2896.1289
B19: 2024 | C19: 3752.3078 | D19: 3989.7309 | E19: 3861.2684 | F19: 3854.5904 | G19: 3750.2828 | H19: 3689.7862 | I19: 3778.3042 | J19: 3780.5811 | K19: 3754.4205 | L19: 3740.7707 | M19: 3773.0592 | N19: 3630.9777 | R19: 2024 | S19: 3029.0459 | T19: 3174.0145 | U19: 3142.289 | V19: 3109.4006 | W19: 3064.2056 | X19: 3021.6534 | Y19: 3070.7655 | Z19: 3090.3774 | AA19: 3063.5308 | AB19: 3107.0332 | AC19: 3088.9914 | AD19: 3068.8346
B20: 2025 | C20: 3813.9909 | D20: 4033.5938 | E20: 3951.0368 | F20: 3872.3585 | G20: 3900.4174 | H20: 3879.4614 | I20: 3849.0237 | J20: 3921.1104 | K20: 3924.9915 | L20: 3969.9886 | M20: 3912.1931 | N20: 3861.0579 | R20: 2025 | S20: 3068.1666 | T20: 3223.8637 | U20: 3207.5872 | V20: 3179.3883 | W20: 3210.2509 | X20: 3175.8145 | Y20: 3268.8681 | Z20: 3211.8943 | AA20: 3248.7954 | AB20: 3003.7165 | AC20: 2939.3435 | AD20: 3135.2614
B21: 2026 | C21: 3970.3703 | D21: 4183.7078 | E21: 4162.9246 | R21: 2026 | S21: 3195.3381 | T21: 3486.9667 | U21: 3426.3783

Sheet ANTIHUMEDAD antes
A2: ANTIHUMEDAD | D2: 0 | E2: 0 | F2: 0 | G2: 0 | H2: 0 | I2: 0 | J2: 0 | K2: 0 | L2: 24 | M2: 26 | N2: 25 | O2: 24 | P2: =SUM(D2:F2) -> 0 | Q2: 26 | R2: 23 | S2: 24 | T2: 24 | U2: 26 | V2: 25 | W2: 27 | X2: 26 | Y2: 25 | Z2: 27 | AA2: 24 | AB2: 25 | AC2: =SUM(Q2:S2) -> 73 | AD2: 26 | AE2: 23 | AF2: 25 | AP2: =SUM(AD2:AO2) -> 74
A3: Region | B3: Gerencia | C3: Plaza | D3: Ene'24 | E3: Feb'24 | F3: Mar'24 | G3: Abr'24 | H3: May'24 | I3: Jun'24 | J3: Jul'24 | K3: Ago'24 | L3: Sep'24 | M3: Oct'24 | N3: Nov'24 | O3: Dic'24 | P3: Acum'24 | Q3: Ene'25 | R3: Feb'25 | S3: Mar'25 | T3: Abr'25 | U3: May'25 | V3: Jun'25 | W3: Jul'25 | X3: Ago'25 | Y3: Sep'25 | Z3: Oct'25 | AA3: Nov'25 | AB3: Dic'25 | AC3: Acum'25 | AD3: Ene'26 | AE3: Feb'26 | AF3: Mar'26 | AG3: Abr'26 | AH3: May'26 | AI3: Jun'26 | AJ3: Jul'26 | AK3: Ago'26 | AL3: Sep'26 | AM3: Oct'26 | AN3: Nov'26 | AO3: Dic'26 | AP3: Acum'26
B4: GUADALAJARA ALTOS | C4: GUADALAJARA | D4: 0 | E4: 0 | F4: 0 | G4: 0 | H4: 0 | I4: 0 | J4: 0 | K4: 0 | L4: 34 | M4: 16 | N4: 37 | O4: 24.475 | P4: =SUM(D4:F4) -> 0 | Q4: 24.1 | R4: 42 | S4: 43 | T4: 46.925 | U4: 46 | V4: 68.4 | W4: 63.65 | X4: 56.1 | Y4: 56.875 | Z4: 53.525 | AA4: 55.4 | AB4: 50.5 | AC4: =SUM(Q4:S4) -> 109.1 | AD4: 84.6 | AE4: 84 | AF4: 0 | AG4: 0 | AH4: 0 | AI4: 0 | AJ4: 0 | AK4: 0 | AL4: 0 | AM4: 0 | AN4: 0 | AO4: 0 | AP4: =SUM(AD4:AO4) -> 168.6
B5: GUADALAJARA ALTOS TOTAL | D5: =SUM(D4) -> 0 | E5: =SUM(E4) -> 0 | F5: =SUM(F4) -> 0 | G5: =SUM(G4) -> 0 | H5: =SUM(H4) -> 0 | I5: =SUM(I4) -> 0 | J5: =SUM(J4) -> 0 | K5: =SUM(K4) -> 0 | ... AP5: =SUM(AP4) -> 168.6
B6: JAL-COL-NAY | C6: COLIMA | D6: 0 | E6: 0 | F6: 0 | G6: 0 | H6: 0 | I6: 0 | J6: 0 | K6: 0 | L6: 4 | M6: 0 | N6: 0.2 | O6: 0 | P6: =SUM(D6:F6) -> 0 | Q6: 0 | R6: 2 | S6: 2 | T6: 8 | U6: 2.1 | V6: 4 | W6: 4.2 | X6: 2 | Y6: 4 | Z6: 6 | AA6: 0 | AB6: 2 | AC6: =SUM(Q6:S6) -> 4 | AD6: 2 | AE6: 4 | AF6: 0 | AG6: 0 | AH6: 0 | AI6: 0 | AJ6: 0 | AK6: 0 | AL6: 0 | AM6: 0 | AN6: 0 | AO6: 0 | AP6: =SUM(AD6:AO6) -> 6
C7: MANZANILLO | D7: 0 | E7: 0 | F7: 0 | G7: 0 | H7: 0 | I7: 0 | J7: 0 | K7: 0 | L7: 4 | M7: 8 | N7: 2.2 | O7: 2 | P7: =SUM(D7:F7) -> 0 | Q7: 2.1 | R7: 2 | S7: 2 | T7: 6 | U7: 8 | V7: 6 | W7: 8 | X7: 8 | Y7: 6 | Z7: 6.1 | AA7: 4 | AB7: 6.1 | AC7: =SUM(Q7:S7) -> 6.1 | AD7: 4 | AE7: 4 | AF7: 0 | AG7: 0 | AH7: 0 | AI7: 0 | AJ7: 0 | AK7: 0 | AL7: 0 | AM7: 0 | AN7: 0 | AO7: 0 | AP7: =SUM(AD7:AO7) -> 8
C8: PUERTO VALLARTA | D8: 0 | E8: 0 | F8: 0 | G8: 0 | H8: 0 | I8: 0 | J8: 0 | K8: 0 | L8: 12 | M8: 0 | N8: 10.2 | O8: 3.75 | P8: =SUM(D8:F8) -> 0 | Q8: 4 | R8: 6 | S8: 4.1 | T8: 6 | U8: 14.2 | V8: 12 | W8: 16 | X8: 10 | Y8: 5.575 | Z8: 14.4 | AA8: 18.3 | AB8: 19.2 | AC8: =SUM(Q8:S8) -> 14.1 | AD8: 5.55 | AE8: 23.2 | AF8: 0 | AG8: 0 | AH8: 0 | AI8: 0 | AJ8: 0 | AK8: 0 | AL8: 0 | AM8: 0 | AN8: 0 | AO8: 0 | AP8: =SUM(AD8:AO8) -> 28.75
C9: TEPIC | D9: 0 | E9: 0 | F9: 0 | G9: 0 | H9: 0 | I9: 0 | J9: 0 | K9: 0 | L9: 6 | M9: 0 | N9: 0.2 | O9: 2 | P9: =SUM(D9:F9) -> 0 | Q9: 6 | R9: 1.875 | S9: 8.5 | T9: 4 | U9: 4 | V9: 16 | W9: 7.95 | X9: 6 | Y9: 6.1 | Z9: 6 | AA9: 4.4 | AB9: 2 | AC9: =SUM(Q9:S9) -> 16.375 | AD9: 2 | AE9: 4 | AF9: 0 | AG9: 0 | AH9: 0 | AI9: 0 | AJ9: 0 | AK9: 0 | AL9: 0 | AM9: 0 | AN9: 0 | AO9: 0 | AP9: =SUM(AD9:AO9) -> 6
B10: JAL-COL-NAY TOTAL | D10: =SUM(D6:D9) -> 0 | E10: =SUM(E6:E9) -> 0 | F10: =SUM(F6:F9) -> 0 | G10: =SUM(G6:G9) -> 0 | H10: =SUM(H6:H9) -> 0 | I10: =SUM(I6:I9) -> 0 | J10: =SUM(J6:J9) -> 0 | K10: =SUM(K6:K9) -> 0 | ... AP10: =SUM(AP6:AP9) -> 48.75
B11: LAS CALIFORNIAS | C11: CABOS | D11: 0 | E11: 0 | F11: 0 | G11: 0 | H11: 0 | I11: 0 | J11: 0 | K11: 0 | L11: 4 | M11: 50.825 | N11: 40.2 | O11: 26 | P11: =SUM(D11:F11) -> 0 | Q11: 0 | R11: 0 | S11: 0.3 | T11: 0 | U11: 10 | V11: 0 | W11: 34 | X11: 16 | Y11: 4 | Z11: 30 | AA11: 12 | AB11: 14 | AC11: =SUM(Q11:S11) -> 0.3 | AD11: 2 | AE11: 0 | AF11: 0 | AG11: 0 | AH11: 0 | AI11: 0 | AJ11: 0 | AK11: 0 | AL11: 0 | AM11: 0 | AN11: 0 | AO11: 0 | AP11: =SUM(AD11:AO11) -> 2
C12: LA PAZ | D12: 0 | E12: 0 | F12: 0 | G12: 0 | H12: 0 | I12: 0 | J12: 0 | K12: 0 | L12: 1.5 | M12: 6 | N12: 0 | O12: 0.2 | P12: =SUM(D12:F12) -> 0 | Q12: 0 | R12: 2 | S12: 2 | T12: 2.1 | U12: 2 | V12: 0 | W12: 2.1 | X12: 0 | Y12: 2.1 | Z12: 2 | AA12: 2 | AB12: 2 | AC12: =SUM(Q12:S12) -> 4 | AD12: 2 | AE12: 4 | AF12: 0 | AG12: 0 | AH12: 0 | AI12: 0 | AJ12: 0 | AK12: 0 | AL12: 0 | AM12: 0 | AN12: 0 | AO12: 0 | AP12: =SUM(AD12:AO12) -> 6
C13: MEXICALI | D13: 0 | E13: 0 | F13: 0 | G13: 0 | H13: 0 | I13: 0 | J13: 0 | K13: 0 | L13: 8.8 | M13: 22 | N13: 64.45 | O13: 4.4 | P13: =SUM(D13:F13) -> 0 | Q13: 44.025 | R13: 19.825 | S13: 19.4 | T13: 70.475 | U13: 54.6 | V13: 61.3 | W13: 0 | X13: 40.8 | Y13: 48.2 | Z13: 30 | AA13: 22 | AB13: 22 | AC13: =SUM(Q13:S13) -> 83.25 | AD13: 27.975 | AE13: 14 | AF13: 0 | AG13: 0 | AH13: 0 | AI13: 0 | AJ13: 0 | AK13: 0 | AL13: 0 | AM13: 0 | AN13: 0 | AO13: 0 | AP13: =SUM(AD13:AO13) -> 41.975
C14: TIJUANA | D14: 0 | E14: 0 | F14: 0 | G14: 0 | H14: 0 | I14: 0 | J14: 0 | K14: 0 | L14: 4.2 | M14: 7.8 | N14: 12.8 | O14: 6.6 | P14: =SUM(D14:F14) -> 0 | Q14: 4.5 | R14: 4.4 | S14: 16 | T14: 17.35 | U14: 6.6 | V14: 4.2 | W14: 12.2 | X14: 2.1 | Y14: 8.6 | Z14: 16.1 | AA14: 22.8 | AB14: 4.5 | AC14: =SUM(Q14:S14) -> 24.9 | AD14: 18.5 | AE14: 21.6 | AF14: 0 | AG14: 0 | AH14: 0 | AI14: 0 | AJ14: 0 | AK14: 0 | AL14: 0 | AM14: 0 | AN14: 0 | AO14: 0 | AP14: =SUM(AD14:AO14) -> 40.1
C15: ROSARITO | D15: 0 | E15: 0 | F15: 0 | G15: 0 | H15: 0 | I15: 0 | J15: 0 | K15: 0 | L15: 2.2 | M15: 6.6 | N15: 2.4 | O15: 2.2 | P15: =SUM(D15:F15) -> 0 | Q15: 4.4 | R15: 0 | S15: 4.4 | T15: 6.6 | U15: 6.6 | V15: 6.3 | W15: 0 | X15: 0 | Y15: 6 | Z15: 6 | AA15: 2.2 | AB15: 2 | AC15: =SUM(Q15:S15) -> 8.8 | AD15: 10.1 | AE15: 5.8 | AF15: 0 | AG15: 0 | AH15: 0 | AI15: 0 | AJ15: 0 | AK15: 0 | AL15: 0 | AM15: 0 | AN15: 0 | AO15: 0 | AP15: =SUM(AD15:AO15) -> 15.9
C16: ENSENADA | D16: 0 | E16: 0 | F16: 0 | G16: 0 | H16: 0 | I16: 0 | J16: 0 | K16: 0 | L16: 2.15 | M16: 2.2 | N16: 0 | O16: 0.1 | P16: =SUM(D16:F16) -> 0 | Q16: 0 | R16: 2.2 | S16: 2.2 | T16: 0 | U16: 2.5 | V16: 4 | W16: 0 | X16: 0 | Y16: 2.2 | Z16: 2 | AA16: 2.3 | AB16: 2 | AC16: =SUM(Q16:S16) -> 4.4 | AD16: 6.8 | AE16: 7.6 | AF16: 0 | AG16: 0 | AH16: 0 | AI16: 0 | AJ16: 0 | AK16: 0 | AL16: 0 | AM16: 0 | AN16: 0 | AO16: 0 | AP16: =SUM(AD16:AO16) -> 14.4
B17: LAS CALIFORNIAS TOTAL | D17: =SUM(D11:D16) -> 0 | E17: =SUM(E11:E16) -> 0 | F17: =SUM(F11:F16) -> 0 | G17: =SUM(G11:G16) -> 0 | H17: =SUM(H11:H16) -> 0 | I17: =SUM(I11:I16) -> 0 | J17: =SUM(J11:J16) -> 0 | K17: =SUM(K11:K16) -> 0 | ... AP17: =SUM(AP11:AP16) -> 120.375
B18: SINALOA | C18: CULIACAN | D18: 0 | E18: 0 | F18: 0 | G18: 0 | H18: 0 | I18: 0 | J18: 0 | K18: 0 | L18: 6 | M18: 0 | N18: 2.3 | O18: 8 | P18: =SUM(D18:F18) -> 0 | Q18: 2 | R18: 0 | S18: 12.1 | T18: 2 | U18: 12 | V18: 6.025 | W18: 8.1 | X18: 2 | Y18: 8.125 | Z18: 5.65 | AA18: 2.2 | AB18: 4 | AC18: =SUM(Q18:S18) -> 14.1 | AD18: 6.1 | AE18: 12 | AF18: 0 | AG18: 0 | AH18: 0 | AI18: 0 | AJ18: 0 | AK18: 0 | AL18: 0 | AM18: 0 | AN18: 0 | AO18: 0 | AP18: =SUM(AD18:AO18) -> 18.1
C19: MAZATLAN | D19: 0 | E19: 0 | F19: 0 | G19: 0 | H19: 0 | I19: 0 | J19: 0 | K19: 0 | L19: 4 | M19: 0 | N19: 4.2 | O19: 2 | P19: =SUM(D19:F19) -> 0 | Q19: 2.1 | R19: 6 | S19: 6.3 | T19: 2 | U19: 2.5 | V19: 6 | W19: 2 | X19: 6 | Y19: 2 | Z19: 8 | AA19: 2 | AB19: 3.225 | AC19: =SUM(Q19:S19) -> 14.4 | AD19: 10.2 | AE19: 2 | AF19: 0 | AG19: 0 | AH19: 0 | AI19: 0 | AJ19: 0 | AK19: 0 | AL19: 0 | AM19: 0 | AN19: 0 | AO19: 0 | AP19: =SUM(AD19:AO19) -> 12.2
C20: MOCHIS | D20: 0 | E20: 0 | F20: 0 | G20: 0 | H20: 0 | I20: 0 | J20: 0 | K20: 0 | L20: 4 | M20: 4 | N20: 6 | O20: 0.1 | P20: =SUM(D20:F20) -> 0 | Q20: 8 | R20: 6 | S20: 4.1 | T20: 4 | U20: 4 | V20: 13.725 | W20: 6 | X20: 4 | Y20: 2.1 | Z20: 6 | AA20: 6.1 | AB20: 4 | AC20: =SUM(Q20:S20) -> 18.1 | AD20: 12 | AE20: 9.9 | AF20: 0 | AG20: 0 | AH20: 0 | AI20: 0 | AJ20: 0 | AK20: 0 | AL20: 0 | AM20: 0 | AN20: 0 | AO20: 0 | AP20: =SUM(AD20:AO20) -> 21.9
C21: GUASAVE | D21: 0 | E21: 0 | F21: 0 | G21: 0 | H21: 0 | I21: 0 | J21: 0 | K21: 0 | L21: 4 | M21: 6 | N21: 2 | O21: 8 | P21: =SUM(D21:F21) -> 0 | Q21: 64.1 | R21: 2 | S21: 8 | T21: 10 | U21: 10 | V21: 4 | W21: 18 | X21: 6 | Y21: 0 | Z21: 12 | AA21: 6 | AB21: 20 | AC21: =SUM(Q21:S21) -> 74.1 | AD21: 14.1 | AE21: 20 | AF21: 0 | AG21: 0 | AH21: 0 | AI21: 0 | AJ21: 0 | AK21: 0 | AL21: 0 | AM21: 0 | AN21: 0 | AO21: 0 | AP21: =SUM(AD21:AO21) -> 34.1
B22: SINALOA TOTAL | D22: =SUM(D18:D21) -> 0 | E22: =SUM(E18:E21) -> 0 | F22: =SUM(F18:F21) -> 0 | G22: =SUM(G18:G21) -> 0 | H22: =SUM(H18:H21) -> 0 | I22: =SUM(I18:I21) -> 0 | J22: =SUM(J18:J21) -> 0 | K22: =SUM(K18:K21) -> 0 | ... AP22: =SUM(AP18:AP21) -> 86.3
B23: SONORA | C23: GUAYMAS | D23: 0 | E23: 0 | F23: 0 | G23: 0 | H23: 0 | I23: 0 | J23: 0 | K23: 0 | L23: 3.8 | M23: 0 | N23: 4.1 | O23: 4 | P23: =SUM(D23:F23) -> 0 | Q23: 2.1 | R23: 8 | S23: 6 | T23: 2 | U23: 0 | V23: 2 | W23: 2 | X23: 2 | Y23: 4.1 | Z23: 4 | AA23: 4 | AB23: 6.1 | AC23: =SUM(Q23:S23) -> 16.1 | AD23: 16 | AE23: 10 | AF23: 0 | AG23: 0 | AH23: 0 | AI23: 0 | AJ23: 0 | AK23: 0 | AL23: 0 | AM23: 0 | AN23: 0 | AO23: 0 | AP23: =SUM(AD23:AO23) -> 26
C24: HERMOSILLO | D24: 0 | E24: 0 | F24: 0 | G24: 0 | H24: 0 | I24: 0 | J24: 0 | K24: 0 | L24: 5.2 | M24: 6 | N24: 0.4 | O24: 0 | P24: =SUM(D24:F24) -> 0 | Q24: 2 | R24: 4 | S24: 4.4 | T24: 2 | U24: 4 | V24: 0 | W24: 2 | X24: 2 | Y24: 4 | Z24: 2 | AA24: 7 | AB24: 2 | AC24: =SUM(Q24:S24) -> 10.4 | AD24: 2.4 | AE24: 6 | AF24: 0 | AG24: 0 | AH24: 0 | AI24: 0 | AJ24: 0 | AK24: 0 | AL24: 0 | AM24: 0 | AN24: 0 | AO24: 0 | AP24: =SUM(AD24:AO24) -> 8.4
C25: NOGALES | D25: 0 | E25: 0 | F25: 0 | G25: 0 | H25: 0 | I25: 0 | J25: 0 | K25: 0 | L25: 4 | M25: 0 | N25: 0.2 | O25: 0 | P25: =SUM(D25:F25) -> 0 | Q25: 0 | R25: 2 | S25: 0 | T25: 2 | U25: 2 | V25: 0 | W25: 2 | X25: 0 | Y25: 0 | Z25: 4 | AA25: 0 | AB25: 2.1 | AC25: =SUM(Q25:S25) -> 2 | AD25: 0 | AE25: 4 | AF25: 0 | AG25: 0 | AH25: 0 | AI25: 0 | AJ25: 0 | AK25: 0 | AL25: 0 | AM25: 0 | AN25: 0 | AO25: 0 | AP25: =SUM(AD25:AO25) -> 4
C26: OBREGON | D26: 0 | E26: 0 | F26: 0 | G26: 0 | H26: 0 | I26: 0 | J26: 0 | K26: 0 | L26: 1.5 | M26: 4 | N26: 0 | O26: 0.1 | P26: =SUM(D26:F26) -> 0 | Q26: 2 | R26: 2 | S26: 2 | T26: 2 | U26: 4 | V26: 0 | W26: 4 | X26: 0 | Y26: 4.1 | Z26: 4 | AA26: 2 | AB26: 0.1 | AC26: =SUM(Q26:S26) -> 6 | AD26: 2 | AE26: 2 | AF26: 0 | AG26: 0 | AH26: 0 | AI26: 0 | AJ26: 0 | AK26: 0 | AL26: 0 | AM26: 0 | AN26: 0 | AO26: 0 | AP26: =SUM(AD26:AO26) -> 4
B27: SONORA TOTAL | D27: =SUM(D23:D26) -> 0 | E27: =SUM(E23:E26) -> 0 | F27: =SUM(F23:F26) -> 0 | G27: =SUM(G23:G26) -> 0 | H27: =SUM(H23:H26) -> 0 | I27: =SUM(I23:I26) -> 0 | J27: =SUM(J23:J26) -> 0 | K27: =SUM(K23:K26) -> 0 | ... AP27: =SUM(AP23:AP26) -> 42.4
A28: PACIFICO TOTAL | D28: =D5+D10+D17+D22+D27 -> 0 | E28: =E5+E10+E17+E22+E27 -> 0 | F28: =F5+F10+F17+F22+F27 -> 0 | G28: =G5+G10+G17+G22+G27 -> 0 | H28: =H5+H10+H17+H22+H27 -> 0 | I28: =I5+I10+I17+I22+I27 -> 0 | J28: =J5+J10+J17+J22+J27 -> 0 | K28: =K5+K10+K17+K22+K27 -> 0 | ... AP28: =AP5+AP10+AP17+AP22+AP27 -> 466.425
A29: NORESTE | B29: SLP-ZAC | C29: SAN LUIS | D29: 0 | E29: 0 | F29: 0 | G29: 0 | H29: 0 | I29: 0 | J29: 0 | K29: 0 | L29: 9 | M29: 9 | N29: 22.7 | O29: 11.9 | P29: =SUM(D29:F29) -> 0 | Q29: 7.15 | R29: 9 | S29: 4.5 | T29: 11.25 | U29: 4.5 | V29: 11.25 | W29: 13.8 | X29: 18 | Y29: 15.95 | Z29: 18 | AA29: 11.25 | AB29: 13.7 | AC29: =SUM(Q29:S29) -> 20.65 | AD29: 15.85 | AE29: 24.75 | AF29: 0 | AG29: 0 | AH29: 0 | AI29: 0 | AJ29: 0 | AK29: 0 | AL29: 0 | AM29: 0 | AN29: 0 | AO29: 0 | AP29: =SUM(AD29:AO29) -> 40.6
C30: ZACATECAS | D30: 0 | E30: 0 | F30: 0 | G30: 0 | H30: 0 | I30: 0 | J30: 0 | K30: 0 | L30: 5 | M30: 2.25 | N30: 2.25 | O30: 0 | P30: =SUM(D30:F30) -> 0 | Q30: 0.2 | R30: 8.975 | S30: 6.75 | T30: 0 | U30: 6.75 | V30: 4.5 | W30: 2.45 | X30: 2.25 | Y30: 9 | Z30: 2.25 | AA30: 4.5 | AB30: 2.25 | AC30: =SUM(Q30:S30) -> 15.925 | AD30: 4.6 | AE30: 4.5 | AF30: 0 | AG30: 0 | AH30: 0 | AI30: 0 | AJ30: 0 | AK30: 0 | AL30: 0 | AM30: 0 | AN30: 0 | AO30: 0 | AP30: =SUM(AD30:AO30) -> 9.1
B31: SLP-ZAC TOTAL | D31: =SUM(D29:D30) -> 0 | E31: =SUM(E29:E30) -> 0 | F31: =SUM(F29:F30) -> 0 | G31: =SUM(G29:G30) -> 0 | H31: =SUM(H29:H30) -> 0 | I31: =SUM(I29:I30) -> 0 | J31: =SUM(J29:J30) -> 0 | K31: =SUM(K29:K30) -> 0 | ... AP31: =SUM(AP29:AP30) -> 49.7
B32: COAHUILA-DURANGO | C32: DURANGO | D32: 0 | E32: 0 | F32: 0 | G32: 0 | H32: 0 | I32: 0 | J32: 0 | K32: 0 | L32: 4.5 | M32: 0 | N32: 2.25 | O32: 2.45 | P32: =SUM(D32:F32) -> 0 | Q32: 2.25 | R32: 2.25 | S32: 2.55 | T32: 4.5 | U32: 4.5 | V32: 4.5 | W32: 9.2 | X32: 6.75 | Y32: 4.6 | Z32: 4.5 | AA32: 6.75 | AB32: 4.8 | AC32: =SUM(Q32:S32) -> 7.05 | AD32: 0 | AE32: 6.75 | AF32: 0 | AG32: 0 | AH32: 0 | AI32: 0 | AJ32: 0 | AK32: 0 | AL32: 0 | AM32: 0 | AN32: 0 | AO32: 0 | AP32: =SUM(AD32:AO32) -> 6.75
C33: MONCLOVA | D33: 0 | E33: 0 | F33: 0 | G33: 0 | H33: 0 | I33: 0 | J33: 0 | K33: 0 | L33: 8.75 | M33: 0 | N33: 2.25 | O33: 9 | P33: =SUM(D33:F33) -> 0 | Q33: 2.45 | R33: 13.5 | S33: 11.25 | T33: 4.5 | U33: 6.75 | V33: 4.5 | W33: 9 | X33: 4.5 | Y33: 8.5 | Z33: 9 | AA33: 6.75 | AB33: 9 | AC33: =SUM(Q33:S33) -> 27.2 | AD33: 2.25 | AE33: 6.75 | AF33: 0 | AG33: 0 | AH33: 0 | AI33: 0 | AJ33: 0 | AK33: 0 | AL33: 0 | AM33: 0 | AN33: 0 | AO33: 0 | AP33: =SUM(AD33:AO33) -> 9
C34: PIEDRAS NEGRAS | D34: 0 | E34: 0 | F34: 0 | G34: 0 | H34: 0 | I34: 0 | J34: 0 | K34: 0 | L34: 0 | M34: 0 | N34: 0.1 | O34: 0 | P34: =SUM(D34:F34) -> 0 | Q34: 0 | R34: 0 | S34: 0.1 | T34: 0 | U34: 0 | V34: 0.1 | W34: 0 | X34: 0.1 | Y34: 0 | Z34: 0 | AA34: 0.3 | AB34: 0 | AC34: =SUM(Q34:S34) -> 0.1 | AD34: 0 | AE34: 0 | AF34: 0 | AG34: 0 | AH34: 0 | AI34: 0 | AJ34: 0 | AK34: 0 | AL34: 0 | AM34: 0 | AN34: 0 | AO34: 0 | AP34: =SUM(AD34:AO34) -> 0
C35: SALTILLO | D35: 0 | E35: 0 | F35: 0 | G35: 0 | H35: 0 | I35: 0 | J35: 0 | K35: 0 | L35: 3.4 | M35: 4.275 | N35: 12.4 | O35: 8.85 | P35: =SUM(D35:F35) -> 0 | Q35: 8.45 | R35: 8.45 | S35: 11.2 | T35: 15.7 | U35: 4.4 | V35: 8.95 | W35: 15.6 | X35: 17.2 | Y35: 10.85 | Z35: 11.05 | AA35: 11.45 | AB35: 15.7 | AC35: =SUM(Q35:S35) -> 28.1 | AD35: 8.5 | AE35: 18 | AF35: 0 | AG35: 0 | AH35: 0 | AI35: 0 | AJ35: 0 | AK35: 0 | AL35: 0 | AM35: 0 | AN35: 0 | AO35: 0 | AP35: =SUM(AD35:AO35) -> 26.5
C36: TORREON | D36: 0 | E36: 0 | F36: 0 | G36: 0 | H36: 0 | I36: 0 | J36: 0 | K36: 0 | L36: 4.4 | M36: 4.5 | N36: 4.2 | O36: 0 | P36: =SUM(D36:F36) -> 0 | Q36: 8.6 | R36: 6 | S36: 0 | T36: 2 | U36: 12.1 | V36: 2 | W36: 2 | X36: 4 | Y36: 4.3 | Z36: 10 | AA36: 4 | AB36: 6 | AC36: =SUM(Q36:S36) -> 14.6 | AD36: 2.3 | AE36: 6 | AF36: 0 | AG36: 0 | AH36: 0 | AI36: 0 | AJ36: 0 | AK36: 0 | AL36: 0 | AM36: 0 | AN36: 0 | AO36: 0 | AP36: =SUM(AD36:AO36) -> 8.3
B37: COAHUILA-DURANGO TOTAL | D37: =SUM(D32:D36) -> 0 | E37: =SUM(E32:E36) -> 0 | F37: =SUM(F32:F36) -> 0 | G37: =SUM(G32:G36) -> 0 | H37: =SUM(H32:H36) -> 0 | I37: =SUM(I32:I36) -> 0 | J37: =SUM(J32:J36) -> 0 | K37: =SUM(K32:K36) -> 0 | ... AP37: =SUM(AP32:AP36) -> 50.55
B38: TAMPS-VER | C38: MATAMOROS | D38: 0 | E38: 0 | F38: 0 | G38: 0 | H38: 0 | I38: 0 | J38: 0 | K38: 0 | L38: 4.5 | M38: 4.5 | N38: 9.2 | O38: 15.65 | P38: =SUM(D38:F38) -> 0 | Q38: 20.25 | R38: 13.5 | S38: 18 | T38: 13 | U38: 31.5 | V38: 24.65 | W38: 24.75 | X38: 15.75 | Y38: 15.75 | Z38: 18 | AA38: 15.75 | AB38: 13.5 | AC38: =SUM(Q38:S38) -> 51.75 | AD38: 6.75 | AE38: 8.45 | AF38: 0 | AG38: 0 | AH38: 0 | AI38: 0 | AJ38: 0 | AK38: 0 | AL38: 0 | AM38: 0 | AN38: 0 | AO38: 0 | AP38: =SUM(AD38:AO38) -> 15.2
C39: N LAREDO | D39: 0 | E39: 0 | F39: 0 | G39: 0 | H39: 0 | I39: 0 | J39: 0 | K39: 0 | L39: 4.4 | M39: 4.4 | N39: 2.2 | O39: 11.1 | P39: =SUM(D39:F39) -> 0 | Q39: 6.6 | R39: 13.2 | S39: 13.3 | T39: 6.75 | U39: 6.6 | V39: 4.375 | W39: 12 | X39: 6 | Y39: 4 | Z39: 10 | AA39: 0.1 | AB39: 0.2 | AC39: =SUM(Q39:S39) -> 33.1 | AD39: 2.1 | AE39: 0 | AF39: 0 | AG39: 0 | AH39: 0 | AI39: 0 | AJ39: 0 | AK39: 0 | AL39: 0 | AM39: 0 | AN39: 0 | AO39: 0 | AP39: =SUM(AD39:AO39) -> 2.1
